return { { ["x"] = 0, ["meta"] = { ["fields"] = {  }, ["inventory"] = {  } }, ["param2"] = 0, ["y"] = 2, ["param1"] = 157, ["z"] = 0, ["name"] = "cottages:roof_straw" }, { ["x"] = 0, ["meta"] = { ["fields"] = {  }, ["inventory"] = {  } }, ["param2"] = 2, ["y"] = 2, ["param1"] = 157, ["z"] = 6, ["name"] = "cottages:roof_straw" }, { ["x"] = 0, ["meta"] = { ["fields"] = {  }, ["inventory"] = {  } }, ["param2"] = 0, ["y"] = 3, ["param1"] = 189, ["z"] = 1, ["name"] = "cottages:roof_straw" }, { ["x"] = 0, ["meta"] = { ["fields"] = {  }, ["inventory"] = {  } }, ["param2"] = 2, ["y"] = 3, ["param1"] = 189, ["z"] = 5, ["name"] = "cottages:roof_straw" }, { ["x"] = 0, ["meta"] = { ["fields"] = {  }, ["inventory"] = {  } }, ["param2"] = 0, ["y"] = 4, ["param1"] = 189, ["z"] = 2, ["name"] = "cottages:roof_straw" }, { ["x"] = 0, ["meta"] = { ["fields"] = {  }, ["inventory"] = {  } }, ["param2"] = 2, ["y"] = 4, ["param1"] = 189, ["z"] = 4, ["name"] = "cottages:roof_straw" }, { ["x"] = 0, ["meta"] = { ["fields"] = {  }, ["inventory"] = {  } }, ["param2"] = 1, ["y"] = 5, ["param1"] = 157, ["z"] = 3, ["name"] = "cottages:roof_flat_straw" }, { ["x"] = 1, ["meta"] = { ["fields"] = {  }, ["inventory"] = {  } }, ["param2"] = 0, ["y"] = 0, ["param1"] = 156, ["z"] = 3, ["name"] = "stairs:slab_wood" }, { ["x"] = 1, ["meta"] = { ["fields"] = {  }, ["inventory"] = {  } }, ["param2"] = 0, ["y"] = 2, ["param1"] = 173, ["z"] = 0, ["name"] = "cottages:roof_straw" }, { ["x"] = 1, ["meta"] = { ["fields"] = {  }, ["inventory"] = {  } }, ["param2"] = 2, ["y"] = 2, ["param1"] = 173, ["z"] = 6, ["name"] = "cottages:roof_straw" }, { ["x"] = 1, ["meta"] = { ["fields"] = {  }, ["inventory"] = {  } }, ["param2"] = 0, ["y"] = 3, ["param1"] = 205, ["z"] = 1, ["name"] = "cottages:roof_straw" }, { ["x"] = 1, ["meta"] = { ["fields"] = {  }, ["inventory"] = {  } }, ["param2"] = 2, ["y"] = 3, ["param1"] = 0, ["z"] = 2, ["name"] = "default:torch" }, { ["x"] = 1, ["meta"] = { ["fields"] = {  }, ["inventory"] = {  } }, ["param2"] = 2, ["y"] = 3, ["param1"] = 0, ["z"] = 4, ["name"] = "default:torch" }, { ["x"] = 1, ["meta"] = { ["fields"] = {  }, ["inventory"] = {  } }, ["param2"] = 2, ["y"] = 3, ["param1"] = 205, ["z"] = 5, ["name"] = "cottages:roof_straw" }, { ["x"] = 1, ["meta"] = { ["fields"] = {  }, ["inventory"] = {  } }, ["param2"] = 0, ["y"] = 4, ["param1"] = 205, ["z"] = 2, ["name"] = "cottages:roof_straw" }, { ["x"] = 1, ["meta"] = { ["fields"] = {  }, ["inventory"] = {  } }, ["param2"] = 2, ["y"] = 4, ["param1"] = 205, ["z"] = 4, ["name"] = "cottages:roof_straw" }, { ["x"] = 1, ["meta"] = { ["fields"] = {  }, ["inventory"] = {  } }, ["param2"] = 1, ["y"] = 5, ["param1"] = 173, ["z"] = 3, ["name"] = "cottages:roof_flat_straw" }, { ["x"] = 2, ["meta"] = { ["fields"] = {  }, ["inventory"] = {  } }, ["param2"] = 0, ["y"] = 0, ["param1"] = 0, ["z"] = 1, ["name"] = "default:tree" }, { ["x"] = 2, ["meta"] = { ["fields"] = {  }, ["inventory"] = {  } }, ["param2"] = 0, ["y"] = 0, ["param1"] = 0, ["z"] = 2, ["name"] = "cottages:loam" }, { ["x"] = 2, ["meta"] = { ["fields"] = {  }, ["inventory"] = {  } }, ["param2"] = 0, ["y"] = 0, ["param1"] = 0, ["z"] = 3, ["name"] = "cottages:loam" }, { ["x"] = 2, ["meta"] = { ["fields"] = {  }, ["inventory"] = {  } }, ["param2"] = 0, ["y"] = 0, ["param1"] = 0, ["z"] = 4, ["name"] = "cottages:loam" }, { ["x"] = 2, ["meta"] = { ["fields"] = {  }, ["inventory"] = {  } }, ["param2"] = 0, ["y"] = 0, ["param1"] = 0, ["z"] = 5, ["name"] = "default:tree" }, { ["x"] = 2, ["meta"] = { ["fields"] = {  }, ["inventory"] = {  } }, ["param2"] = 0, ["y"] = 1, ["param1"] = 0, ["z"] = 1, ["name"] = "default:tree" }, { ["x"] = 2, ["meta"] = { ["fields"] = {  }, ["inventory"] = {  } }, ["param2"] = 0, ["y"] = 1, ["param1"] = 0, ["z"] = 2, ["name"] = "cottages:loam" }, { ["x"] = 2, ["meta"] = { ["fields"] = {  }, ["inventory"] = {  } }, ["param2"] = 1, ["y"] = 1, ["param1"] = 155, ["z"] = 3, ["name"] = "doors:door_wood_b_1" }, { ["x"] = 2, ["meta"] = { ["fields"] = {  }, ["inventory"] = {  } }, ["param2"] = 0, ["y"] = 1, ["param1"] = 0, ["z"] = 4, ["name"] = "cottages:loam" }, { ["x"] = 2, ["meta"] = { ["fields"] = {  }, ["inventory"] = {  } }, ["param2"] = 0, ["y"] = 1, ["param1"] = 0, ["z"] = 5, ["name"] = "default:tree" }, { ["x"] = 2, ["meta"] = { ["fields"] = {  }, ["inventory"] = {  } }, ["param2"] = 0, ["y"] = 2, ["param1"] = 157, ["z"] = 0, ["name"] = "cottages:roof_straw" }, { ["x"] = 2, ["meta"] = { ["fields"] = {  }, ["inventory"] = {  } }, ["param2"] = 0, ["y"] = 2, ["param1"] = 0, ["z"] = 1, ["name"] = "default:tree" }, { ["x"] = 2, ["meta"] = { ["fields"] = {  }, ["inventory"] = {  } }, ["param2"] = 0, ["y"] = 2, ["param1"] = 0, ["z"] = 2, ["name"] = "cottages:loam" }, { ["x"] = 2, ["meta"] = { ["fields"] = {  }, ["inventory"] = {  } }, ["param2"] = 1, ["y"] = 2, ["param1"] = 171, ["z"] = 3, ["name"] = "doors:door_wood_t_1" }, { ["x"] = 2, ["meta"] = { ["fields"] = {  }, ["inventory"] = {  } }, ["param2"] = 0, ["y"] = 2, ["param1"] = 0, ["z"] = 4, ["name"] = "cottages:loam" }, { ["x"] = 2, ["meta"] = { ["fields"] = {  }, ["inventory"] = {  } }, ["param2"] = 0, ["y"] = 2, ["param1"] = 0, ["z"] = 5, ["name"] = "default:tree" }, { ["x"] = 2, ["meta"] = { ["fields"] = {  }, ["inventory"] = {  } }, ["param2"] = 2, ["y"] = 2, ["param1"] = 173, ["z"] = 6, ["name"] = "cottages:roof_straw" }, { ["x"] = 2, ["meta"] = { ["fields"] = {  }, ["inventory"] = {  } }, ["param2"] = 0, ["y"] = 3, ["param1"] = 189, ["z"] = 1, ["name"] = "cottages:roof_connector_straw" }, { ["x"] = 2, ["meta"] = { ["fields"] = {  }, ["inventory"] = {  } }, ["param2"] = 0, ["y"] = 3, ["param1"] = 0, ["z"] = 2, ["name"] = "cottages:loam" }, { ["x"] = 2, ["meta"] = { ["fields"] = {  }, ["inventory"] = {  } }, ["param2"] = 0, ["y"] = 3, ["param1"] = 0, ["z"] = 3, ["name"] = "cottages:loam" }, { ["x"] = 2, ["meta"] = { ["fields"] = {  }, ["inventory"] = {  } }, ["param2"] = 0, ["y"] = 3, ["param1"] = 0, ["z"] = 4, ["name"] = "cottages:loam" }, { ["x"] = 2, ["meta"] = { ["fields"] = {  }, ["inventory"] = {  } }, ["param2"] = 2, ["y"] = 3, ["param1"] = 189, ["z"] = 5, ["name"] = "cottages:roof_connector_straw" }, { ["x"] = 2, ["meta"] = { ["fields"] = {  }, ["inventory"] = {  } }, ["param2"] = 0, ["y"] = 4, ["param1"] = 189, ["z"] = 2, ["name"] = "cottages:roof_connector_straw" }, { ["x"] = 2, ["meta"] = { ["fields"] = {  }, ["inventory"] = {  } }, ["param2"] = 0, ["y"] = 4, ["param1"] = 172, ["z"] = 3, ["name"] = "default:fence_wood" }, { ["x"] = 2, ["meta"] = { ["fields"] = {  }, ["inventory"] = {  } }, ["param2"] = 2, ["y"] = 4, ["param1"] = 189, ["z"] = 4, ["name"] = "cottages:roof_connector_straw" }, { ["x"] = 2, ["meta"] = { ["fields"] = {  }, ["inventory"] = {  } }, ["param2"] = 1, ["y"] = 5, ["param1"] = 157, ["z"] = 3, ["name"] = "cottages:roof_flat_straw" }, { ["x"] = 3, ["meta"] = { ["fields"] = {  }, ["inventory"] = {  } }, ["param2"] = 0, ["y"] = 0, ["param1"] = 0, ["z"] = 1, ["name"] = "cottages:loam" }, { ["x"] = 3, ["meta"] = { ["fields"] = {  }, ["inventory"] = {  } }, ["param2"] = 0, ["y"] = 0, ["param1"] = 0, ["z"] = 2, ["name"] = "cottages:loam" }, { ["x"] = 3, ["meta"] = { ["fields"] = {  }, ["inventory"] = {  } }, ["param2"] = 0, ["y"] = 0, ["param1"] = 0, ["z"] = 3, ["name"] = "cottages:loam" }, { ["x"] = 3, ["meta"] = { ["fields"] = {  }, ["inventory"] = {  } }, ["param2"] = 0, ["y"] = 0, ["param1"] = 0, ["z"] = 4, ["name"] = "cottages:loam" }, { ["x"] = 3, ["meta"] = { ["fields"] = {  }, ["inventory"] = {  } }, ["param2"] = 0, ["y"] = 0, ["param1"] = 0, ["z"] = 5, ["name"] = "cottages:loam" }, { ["x"] = 3, ["meta"] = { ["fields"] = {  }, ["inventory"] = {  } }, ["param2"] = 0, ["y"] = 1, ["param1"] = 0, ["z"] = 1, ["name"] = "cottages:loam" }, { ["x"] = 3, ["meta"] = { ["fields"] = {  }, ["inventory"] = {  } }, ["param2"] = 2, ["y"] = 1, ["param1"] = 122, ["z"] = 2, ["name"] = "cottages:bench" }, { ["x"] = 3, ["meta"] = { ["fields"] = {  }, ["inventory"] = {  } }, ["param2"] = 0, ["y"] = 1, ["param1"] = 122, ["z"] = 4, ["name"] = "cottages:bench" }, { ["x"] = 3, ["meta"] = { ["fields"] = {  }, ["inventory"] = {  } }, ["param2"] = 0, ["y"] = 1, ["param1"] = 0, ["z"] = 5, ["name"] = "cottages:loam" }, { ["x"] = 3, ["meta"] = { ["fields"] = {  }, ["inventory"] = {  } }, ["param2"] = 0, ["y"] = 2, ["param1"] = 173, ["z"] = 0, ["name"] = "cottages:roof_straw" }, { ["x"] = 3, ["meta"] = { ["fields"] = {  }, ["inventory"] = {  } }, ["param2"] = 0, ["y"] = 2, ["param1"] = 0, ["z"] = 1, ["name"] = "cottages:loam" }, { ["x"] = 3, ["meta"] = { ["fields"] = {  }, ["inventory"] = {  } }, ["param2"] = 0, ["y"] = 2, ["param1"] = 0, ["z"] = 5, ["name"] = "cottages:loam" }, { ["x"] = 3, ["meta"] = { ["fields"] = {  }, ["inventory"] = {  } }, ["param2"] = 2, ["y"] = 2, ["param1"] = 189, ["z"] = 6, ["name"] = "cottages:roof_straw" }, { ["x"] = 3, ["meta"] = { ["fields"] = {  }, ["inventory"] = {  } }, ["param2"] = 0, ["y"] = 3, ["param1"] = 173, ["z"] = 1, ["name"] = "cottages:roof_connector_straw" }, { ["x"] = 3, ["meta"] = { ["fields"] = {  }, ["inventory"] = {  } }, ["param2"] = 2, ["y"] = 3, ["param1"] = 173, ["z"] = 5, ["name"] = "cottages:roof_connector_straw" }, { ["x"] = 3, ["meta"] = { ["fields"] = {  }, ["inventory"] = {  } }, ["param2"] = 0, ["y"] = 4, ["param1"] = 173, ["z"] = 2, ["name"] = "cottages:roof_straw" }, { ["x"] = 3, ["meta"] = { ["fields"] = {  }, ["inventory"] = {  } }, ["param2"] = 2, ["y"] = 4, ["param1"] = 173, ["z"] = 4, ["name"] = "cottages:roof_straw" }, { ["x"] = 3, ["meta"] = { ["fields"] = {  }, ["inventory"] = {  } }, ["param2"] = 3, ["y"] = 5, ["param1"] = 141, ["z"] = 3, ["name"] = "cottages:roof_flat_straw" }, { ["x"] = 4, ["meta"] = { ["fields"] = {  }, ["inventory"] = {  } }, ["param2"] = 0, ["y"] = 0, ["param1"] = 0, ["z"] = 1, ["name"] = "cottages:loam" }, { ["x"] = 4, ["meta"] = { ["fields"] = {  }, ["inventory"] = {  } }, ["param2"] = 0, ["y"] = 0, ["param1"] = 0, ["z"] = 2, ["name"] = "cottages:loam" }, { ["x"] = 4, ["meta"] = { ["fields"] = {  }, ["inventory"] = {  } }, ["param2"] = 0, ["y"] = 0, ["param1"] = 0, ["z"] = 3, ["name"] = "cottages:loam" }, { ["x"] = 4, ["meta"] = { ["fields"] = {  }, ["inventory"] = {  } }, ["param2"] = 0, ["y"] = 0, ["param1"] = 0, ["z"] = 4, ["name"] = "cottages:loam" }, { ["x"] = 4, ["meta"] = { ["fields"] = {  }, ["inventory"] = {  } }, ["param2"] = 0, ["y"] = 0, ["param1"] = 0, ["z"] = 5, ["name"] = "cottages:loam" }, { ["x"] = 4, ["meta"] = { ["fields"] = {  }, ["inventory"] = {  } }, ["param2"] = 0, ["y"] = 1, ["param1"] = 0, ["z"] = 1, ["name"] = "cottages:loam" }, { ["x"] = 4, ["meta"] = { ["fields"] = { ["src_totaltime"] = "0", ["formspec"] = "size[8,9]image[2,2;1,1;default_furnace_fire_bg.png]list[current_name;fuel;2,3;1,1;]list[current_name;src;2,1;1,1;]list[current_name;dst;5,1;2,2;]list[current_player;main;0,5;8,4;]", ["fuel_time"] = "0", ["fuel_totaltime"] = "0", ["src_time"] = "0", ["infotext"] = "Furnace out of fuel" }, ["inventory"] = { ["fuel"] = { "" }, ["dst"] = { "", "", "", "" }, ["src"] = { "" } } }, ["param2"] = 2, ["y"] = 1, ["param1"] = 0, ["z"] = 2, ["name"] = "default:furnace" }, { ["x"] = 4, ["meta"] = { ["fields"] = {  }, ["inventory"] = {  } }, ["param2"] = 0, ["y"] = 1, ["param1"] = 122, ["z"] = 4, ["name"] = "cottages:bench" }, { ["x"] = 4, ["meta"] = { ["fields"] = {  }, ["inventory"] = {  } }, ["param2"] = 0, ["y"] = 1, ["param1"] = 0, ["z"] = 5, ["name"] = "cottages:loam" }, { ["x"] = 4, ["meta"] = { ["fields"] = {  }, ["inventory"] = {  } }, ["param2"] = 5, ["y"] = 1, ["param1"] = 0, ["z"] = 6, ["name"] = "default:torch" }, { ["x"] = 4, ["meta"] = { ["fields"] = {  }, ["inventory"] = {  } }, ["param2"] = 0, ["y"] = 2, ["param1"] = 189, ["z"] = 0, ["name"] = "cottages:roof_straw" }, { ["x"] = 4, ["meta"] = { ["fields"] = {  }, ["inventory"] = {  } }, ["param2"] = 0, ["y"] = 2, ["param1"] = 0, ["z"] = 1, ["name"] = "cottages:loam" }, { ["x"] = 4, ["meta"] = { ["fields"] = {  }, ["inventory"] = {  } }, ["param2"] = 0, ["y"] = 2, ["param1"] = 0, ["z"] = 5, ["name"] = "cottages:loam" }, { ["x"] = 4, ["meta"] = { ["fields"] = {  }, ["inventory"] = {  } }, ["param2"] = 2, ["y"] = 2, ["param1"] = 205, ["z"] = 6, ["name"] = "cottages:roof_straw" }, { ["x"] = 4, ["meta"] = { ["fields"] = {  }, ["inventory"] = {  } }, ["param2"] = 0, ["y"] = 3, ["param1"] = 157, ["z"] = 1, ["name"] = "cottages:roof_connector_straw" }, { ["x"] = 4, ["meta"] = { ["fields"] = {  }, ["inventory"] = {  } }, ["param2"] = 2, ["y"] = 3, ["param1"] = 173, ["z"] = 5, ["name"] = "cottages:roof_connector_straw" }, { ["x"] = 4, ["meta"] = { ["fields"] = {  }, ["inventory"] = {  } }, ["param2"] = 0, ["y"] = 4, ["param1"] = 157, ["z"] = 2, ["name"] = "cottages:roof_straw" }, { ["x"] = 4, ["meta"] = { ["fields"] = {  }, ["inventory"] = {  } }, ["param2"] = 2, ["y"] = 4, ["param1"] = 157, ["z"] = 4, ["name"] = "cottages:roof_straw" }, { ["x"] = 4, ["meta"] = { ["fields"] = {  }, ["inventory"] = {  } }, ["param2"] = 3, ["y"] = 5, ["param1"] = 125, ["z"] = 3, ["name"] = "cottages:roof_flat_straw" }, { ["x"] = 5, ["meta"] = { ["fields"] = {  }, ["inventory"] = {  } }, ["param2"] = 0, ["y"] = 0, ["param1"] = 0, ["z"] = 1, ["name"] = "cottages:loam" }, { ["x"] = 5, ["meta"] = { ["fields"] = {  }, ["inventory"] = {  } }, ["param2"] = 0, ["y"] = 0, ["param1"] = 0, ["z"] = 2, ["name"] = "cottages:loam" }, { ["x"] = 5, ["meta"] = { ["fields"] = {  }, ["inventory"] = {  } }, ["param2"] = 0, ["y"] = 0, ["param1"] = 0, ["z"] = 3, ["name"] = "cottages:loam" }, { ["x"] = 5, ["meta"] = { ["fields"] = {  }, ["inventory"] = {  } }, ["param2"] = 0, ["y"] = 0, ["param1"] = 0, ["z"] = 4, ["name"] = "cottages:loam" }, { ["x"] = 5, ["meta"] = { ["fields"] = {  }, ["inventory"] = {  } }, ["param2"] = 0, ["y"] = 0, ["param1"] = 0, ["z"] = 5, ["name"] = "cottages:loam" }, { ["x"] = 5, ["meta"] = { ["fields"] = {  }, ["inventory"] = {  } }, ["param2"] = 4, ["y"] = 1, ["param1"] = 0, ["z"] = 0, ["name"] = "default:torch" }, { ["x"] = 5, ["meta"] = { ["fields"] = {  }, ["inventory"] = {  } }, ["param2"] = 0, ["y"] = 1, ["param1"] = 0, ["z"] = 1, ["name"] = "cottages:loam" }, { ["x"] = 5, ["meta"] = { ["fields"] = {  }, ["inventory"] = {  } }, ["param2"] = 0, ["y"] = 1, ["param1"] = 0, ["z"] = 2, ["name"] = "default:wood" }, { ["x"] = 5, ["meta"] = { ["fields"] = {  }, ["inventory"] = {  } }, ["param2"] = 0, ["y"] = 1, ["param1"] = 0, ["z"] = 5, ["name"] = "cottages:loam" }, { ["x"] = 5, ["meta"] = { ["fields"] = {  }, ["inventory"] = {  } }, ["param2"] = 0, ["y"] = 2, ["param1"] = 205, ["z"] = 0, ["name"] = "cottages:roof_straw" }, { ["x"] = 5, ["meta"] = { ["fields"] = {  }, ["inventory"] = {  } }, ["param2"] = 0, ["y"] = 2, ["param1"] = 0, ["z"] = 1, ["name"] = "cottages:loam" }, { ["x"] = 5, ["meta"] = { ["fields"] = {  }, ["inventory"] = {  } }, ["param2"] = 0, ["y"] = 2, ["param1"] = 172, ["z"] = 5, ["name"] = "default:fence_wood" }, { ["x"] = 5, ["meta"] = { ["fields"] = {  }, ["inventory"] = {  } }, ["param2"] = 2, ["y"] = 2, ["param1"] = 189, ["z"] = 6, ["name"] = "cottages:roof_straw" }, { ["x"] = 5, ["meta"] = { ["fields"] = {  }, ["inventory"] = {  } }, ["param2"] = 0, ["y"] = 3, ["param1"] = 173, ["z"] = 1, ["name"] = "cottages:roof_connector_straw" }, { ["x"] = 5, ["meta"] = { ["fields"] = {  }, ["inventory"] = {  } }, ["param2"] = 2, ["y"] = 3, ["param1"] = 157, ["z"] = 5, ["name"] = "cottages:roof_connector_straw" }, { ["x"] = 5, ["meta"] = { ["fields"] = {  }, ["inventory"] = {  } }, ["param2"] = 0, ["y"] = 4, ["param1"] = 141, ["z"] = 2, ["name"] = "cottages:roof_straw" }, { ["x"] = 5, ["meta"] = { ["fields"] = {  }, ["inventory"] = {  } }, ["param2"] = 2, ["y"] = 4, ["param1"] = 141, ["z"] = 4, ["name"] = "cottages:roof_straw" }, { ["x"] = 5, ["meta"] = { ["fields"] = {  }, ["inventory"] = {  } }, ["param2"] = 3, ["y"] = 5, ["param1"] = 141, ["z"] = 3, ["name"] = "cottages:roof_flat_straw" }, { ["x"] = 6, ["meta"] = { ["fields"] = {  }, ["inventory"] = {  } }, ["param2"] = 0, ["y"] = 0, ["param1"] = 0, ["z"] = 1, ["name"] = "cottages:loam" }, { ["x"] = 6, ["meta"] = { ["fields"] = {  }, ["inventory"] = {  } }, ["param2"] = 0, ["y"] = 0, ["param1"] = 0, ["z"] = 2, ["name"] = "cottages:loam" }, { ["x"] = 6, ["meta"] = { ["fields"] = {  }, ["inventory"] = {  } }, ["param2"] = 0, ["y"] = 0, ["param1"] = 0, ["z"] = 3, ["name"] = "cottages:loam" }, { ["x"] = 6, ["meta"] = { ["fields"] = {  }, ["inventory"] = {  } }, ["param2"] = 0, ["y"] = 0, ["param1"] = 0, ["z"] = 4, ["name"] = "cottages:loam" }, { ["x"] = 6, ["meta"] = { ["fields"] = {  }, ["inventory"] = {  } }, ["param2"] = 0, ["y"] = 0, ["param1"] = 0, ["z"] = 5, ["name"] = "cottages:loam" }, { ["x"] = 6, ["meta"] = { ["fields"] = {  }, ["inventory"] = {  } }, ["param2"] = 0, ["y"] = 1, ["param1"] = 0, ["z"] = 1, ["name"] = "cottages:loam" }, { ["x"] = 6, ["meta"] = { ["fields"] = {  }, ["inventory"] = {  } }, ["param2"] = 2, ["y"] = 1, ["param1"] = 106, ["z"] = 2, ["name"] = "cottages:bed_head" }, { ["x"] = 6, ["meta"] = { ["fields"] = {  }, ["inventory"] = {  } }, ["param2"] = 2, ["y"] = 1, ["param1"] = 121, ["z"] = 3, ["name"] = "cottages:bed_foot" }, { ["x"] = 6, ["meta"] = { ["fields"] = { ["infotext"] = "Chest", ["formspec"] = "size[8,9]list[current_name;main;0,0;8,4;]list[current_player;main;0,5;8,4;]" }, ["inventory"] = { ["main"] = { "", "", "", "", "", "", "", "", "", "", "", "", "", "", "", "", "", "", "", "", "", "", "", "", "", "", "", "", "", "", "", "" } } }, ["param2"] = 1, ["y"] = 1, ["param1"] = 0, ["z"] = 4, ["name"] = "default:chest" }, { ["x"] = 6, ["meta"] = { ["fields"] = {  }, ["inventory"] = {  } }, ["param2"] = 0, ["y"] = 1, ["param1"] = 0, ["z"] = 5, ["name"] = "cottages:loam" }, { ["x"] = 6, ["meta"] = { ["fields"] = {  }, ["inventory"] = {  } }, ["param2"] = 0, ["y"] = 2, ["param1"] = 189, ["z"] = 0, ["name"] = "cottages:roof_straw" }, { ["x"] = 6, ["meta"] = { ["fields"] = {  }, ["inventory"] = {  } }, ["param2"] = 0, ["y"] = 2, ["param1"] = 0, ["z"] = 1, ["name"] = "cottages:loam" }, { ["x"] = 6, ["meta"] = { ["fields"] = {  }, ["inventory"] = {  } }, ["param2"] = 0, ["y"] = 2, ["param1"] = 0, ["z"] = 5, ["name"] = "cottages:loam" }, { ["x"] = 6, ["meta"] = { ["fields"] = {  }, ["inventory"] = {  } }, ["param2"] = 2, ["y"] = 2, ["param1"] = 173, ["z"] = 6, ["name"] = "cottages:roof_straw" }, { ["x"] = 6, ["meta"] = { ["fields"] = {  }, ["inventory"] = {  } }, ["param2"] = 0, ["y"] = 3, ["param1"] = 157, ["z"] = 1, ["name"] = "cottages:roof_connector_straw" }, { ["x"] = 6, ["meta"] = { ["fields"] = {  }, ["inventory"] = {  } }, ["param2"] = 2, ["y"] = 3, ["param1"] = 157, ["z"] = 5, ["name"] = "cottages:roof_connector_straw" }, { ["x"] = 6, ["meta"] = { ["fields"] = {  }, ["inventory"] = {  } }, ["param2"] = 0, ["y"] = 4, ["param1"] = 157, ["z"] = 2, ["name"] = "cottages:roof_straw" }, { ["x"] = 6, ["meta"] = { ["fields"] = {  }, ["inventory"] = {  } }, ["param2"] = 2, ["y"] = 4, ["param1"] = 157, ["z"] = 4, ["name"] = "cottages:roof_straw" }, { ["x"] = 6, ["meta"] = { ["fields"] = {  }, ["inventory"] = {  } }, ["param2"] = 3, ["y"] = 5, ["param1"] = 157, ["z"] = 3, ["name"] = "cottages:roof_flat_straw" }, { ["x"] = 7, ["meta"] = { ["fields"] = {  }, ["inventory"] = {  } }, ["param2"] = 0, ["y"] = 0, ["param1"] = 0, ["z"] = 1, ["name"] = "default:tree" }, { ["x"] = 7, ["meta"] = { ["fields"] = {  }, ["inventory"] = {  } }, ["param2"] = 0, ["y"] = 0, ["param1"] = 0, ["z"] = 2, ["name"] = "cottages:loam" }, { ["x"] = 7, ["meta"] = { ["fields"] = {  }, ["inventory"] = {  } }, ["param2"] = 0, ["y"] = 0, ["param1"] = 0, ["z"] = 3, ["name"] = "cottages:loam" }, { ["x"] = 7, ["meta"] = { ["fields"] = {  }, ["inventory"] = {  } }, ["param2"] = 0, ["y"] = 0, ["param1"] = 0, ["z"] = 4, ["name"] = "cottages:loam" }, { ["x"] = 7, ["meta"] = { ["fields"] = {  }, ["inventory"] = {  } }, ["param2"] = 0, ["y"] = 0, ["param1"] = 0, ["z"] = 5, ["name"] = "default:tree" }, { ["x"] = 7, ["meta"] = { ["fields"] = {  }, ["inventory"] = {  } }, ["param2"] = 0, ["y"] = 1, ["param1"] = 0, ["z"] = 1, ["name"] = "default:tree" }, { ["x"] = 7, ["meta"] = { ["fields"] = {  }, ["inventory"] = {  } }, ["param2"] = 0, ["y"] = 1, ["param1"] = 0, ["z"] = 2, ["name"] = "cottages:loam" }, { ["x"] = 7, ["meta"] = { ["fields"] = {  }, ["inventory"] = {  } }, ["param2"] = 0, ["y"] = 1, ["param1"] = 0, ["z"] = 3, ["name"] = "cottages:loam" }, { ["x"] = 7, ["meta"] = { ["fields"] = {  }, ["inventory"] = {  } }, ["param2"] = 0, ["y"] = 1, ["param1"] = 0, ["z"] = 4, ["name"] = "cottages:loam" }, { ["x"] = 7, ["meta"] = { ["fields"] = {  }, ["inventory"] = {  } }, ["param2"] = 0, ["y"] = 1, ["param1"] = 0, ["z"] = 5, ["name"] = "default:tree" }, { ["x"] = 7, ["meta"] = { ["fields"] = {  }, ["inventory"] = {  } }, ["param2"] = 0, ["y"] = 2, ["param1"] = 173, ["z"] = 0, ["name"] = "cottages:roof_straw" }, { ["x"] = 7, ["meta"] = { ["fields"] = {  }, ["inventory"] = {  } }, ["param2"] = 0, ["y"] = 2, ["param1"] = 0, ["z"] = 1, ["name"] = "default:tree" }, { ["x"] = 7, ["meta"] = { ["fields"] = {  }, ["inventory"] = {  } }, ["param2"] = 0, ["y"] = 2, ["param1"] = 0, ["z"] = 2, ["name"] = "cottages:loam" }, { ["x"] = 7, ["meta"] = { ["fields"] = {  }, ["inventory"] = {  } }, ["param2"] = 0, ["y"] = 2, ["param1"] = 0, ["z"] = 3, ["name"] = "cottages:loam" }, { ["x"] = 7, ["meta"] = { ["fields"] = {  }, ["inventory"] = {  } }, ["param2"] = 0, ["y"] = 2, ["param1"] = 172, ["z"] = 4, ["name"] = "default:fence_wood" }, { ["x"] = 7, ["meta"] = { ["fields"] = {  }, ["inventory"] = {  } }, ["param2"] = 0, ["y"] = 2, ["param1"] = 0, ["z"] = 5, ["name"] = "default:tree" }, { ["x"] = 7, ["meta"] = { ["fields"] = {  }, ["inventory"] = {  } }, ["param2"] = 2, ["y"] = 2, ["param1"] = 157, ["z"] = 6, ["name"] = "cottages:roof_straw" }, { ["x"] = 7, ["meta"] = { ["fields"] = {  }, ["inventory"] = {  } }, ["param2"] = 0, ["y"] = 3, ["param1"] = 173, ["z"] = 1, ["name"] = "cottages:roof_connector_straw" }, { ["x"] = 7, ["meta"] = { ["fields"] = {  }, ["inventory"] = {  } }, ["param2"] = 0, ["y"] = 3, ["param1"] = 0, ["z"] = 2, ["name"] = "cottages:loam" }, { ["x"] = 7, ["meta"] = { ["fields"] = {  }, ["inventory"] = {  } }, ["param2"] = 0, ["y"] = 3, ["param1"] = 0, ["z"] = 3, ["name"] = "cottages:loam" }, { ["x"] = 7, ["meta"] = { ["fields"] = {  }, ["inventory"] = {  } }, ["param2"] = 0, ["y"] = 3, ["param1"] = 0, ["z"] = 4, ["name"] = "cottages:loam" }, { ["x"] = 7, ["meta"] = { ["fields"] = {  }, ["inventory"] = {  } }, ["param2"] = 2, ["y"] = 3, ["param1"] = 173, ["z"] = 5, ["name"] = "cottages:roof_connector_straw" }, { ["x"] = 7, ["meta"] = { ["fields"] = {  }, ["inventory"] = {  } }, ["param2"] = 0, ["y"] = 4, ["param1"] = 173, ["z"] = 2, ["name"] = "cottages:roof_connector_straw" }, { ["x"] = 7, ["meta"] = { ["fields"] = {  }, ["inventory"] = {  } }, ["param2"] = 0, ["y"] = 4, ["param1"] = 0, ["z"] = 3, ["name"] = "cottages:loam" }, { ["x"] = 7, ["meta"] = { ["fields"] = {  }, ["inventory"] = {  } }, ["param2"] = 2, ["y"] = 4, ["param1"] = 173, ["z"] = 4, ["name"] = "cottages:roof_connector_straw" }, { ["x"] = 7, ["meta"] = { ["fields"] = {  }, ["inventory"] = {  } }, ["param2"] = 3, ["y"] = 5, ["param1"] = 173, ["z"] = 3, ["name"] = "cottages:roof_flat_straw" }, { ["x"] = 8, ["meta"] = { ["fields"] = {  }, ["inventory"] = {  } }, ["param2"] = 0, ["y"] = 2, ["param1"] = 157, ["z"] = 0, ["name"] = "cottages:roof_straw" }, { ["x"] = 8, ["meta"] = { ["fields"] = {  }, ["inventory"] = {  } }, ["param2"] = 2, ["y"] = 2, ["param1"] = 157, ["z"] = 6, ["name"] = "cottages:roof_straw" }, { ["x"] = 8, ["meta"] = { ["fields"] = {  }, ["inventory"] = {  } }, ["param2"] = 0, ["y"] = 3, ["param1"] = 189, ["z"] = 1, ["name"] = "cottages:roof_straw" }, { ["x"] = 8, ["meta"] = { ["fields"] = {  }, ["inventory"] = {  } }, ["param2"] = 3, ["y"] = 3, ["param1"] = 0, ["z"] = 3, ["name"] = "default:torch" }, { ["x"] = 8, ["meta"] = { ["fields"] = {  }, ["inventory"] = {  } }, ["param2"] = 2, ["y"] = 3, ["param1"] = 189, ["z"] = 5, ["name"] = "cottages:roof_straw" }, { ["x"] = 8, ["meta"] = { ["fields"] = {  }, ["inventory"] = {  } }, ["param2"] = 0, ["y"] = 4, ["param1"] = 189, ["z"] = 2, ["name"] = "cottages:roof_straw" }, { ["x"] = 8, ["meta"] = { ["fields"] = {  }, ["inventory"] = {  } }, ["param2"] = 2, ["y"] = 4, ["param1"] = 189, ["z"] = 4, ["name"] = "cottages:roof_straw" }, { ["x"] = 8, ["meta"] = { ["fields"] = {  }, ["inventory"] = {  } }, ["param2"] = 3, ["y"] = 5, ["param1"] = 189, ["z"] = 3, ["name"] = "cottages:roof_flat_straw" } }