return { { ["x"] = 0, ["meta"] = { ["fields"] = {  }, ["inventory"] = {  } }, ["param2"] = 0, ["y"] = 0, ["param1"] = 0, ["z"] = 1, ["name"] = "default:wood" }, { ["x"] = 0, ["meta"] = { ["fields"] = {  }, ["inventory"] = {  } }, ["param2"] = 0, ["y"] = 0, ["param1"] = 0, ["z"] = 2, ["name"] = "default:wood" }, { ["x"] = 0, ["meta"] = { ["fields"] = {  }, ["inventory"] = {  } }, ["param2"] = 0, ["y"] = 0, ["param1"] = 0, ["z"] = 3, ["name"] = "default:wood" }, { ["x"] = 0, ["meta"] = { ["fields"] = {  }, ["inventory"] = {  } }, ["param2"] = 0, ["y"] = 0, ["param1"] = 0, ["z"] = 4, ["name"] = "default:wood" }, { ["x"] = 0, ["meta"] = { ["fields"] = {  }, ["inventory"] = {  } }, ["param2"] = 0, ["y"] = 0, ["param1"] = 0, ["z"] = 5, ["name"] = "default:wood" }, { ["x"] = 0, ["meta"] = { ["fields"] = {  }, ["inventory"] = {  } }, ["param2"] = 0, ["y"] = 0, ["param1"] = 15, ["z"] = 6, ["name"] = "default:wood" }, { ["x"] = 0, ["meta"] = { ["fields"] = {  }, ["inventory"] = {  } }, ["param2"] = 0, ["y"] = 0, ["param1"] = 15, ["z"] = 7, ["name"] = "default:wood" }, { ["x"] = 0, ["meta"] = { ["fields"] = {  }, ["inventory"] = {  } }, ["param2"] = 0, ["y"] = 0, ["param1"] = 0, ["z"] = 8, ["name"] = "default:wood" }, { ["x"] = 0, ["meta"] = { ["fields"] = {  }, ["inventory"] = {  } }, ["param2"] = 0, ["y"] = 0, ["param1"] = 0, ["z"] = 9, ["name"] = "default:wood" }, { ["x"] = 0, ["meta"] = { ["fields"] = {  }, ["inventory"] = {  } }, ["param2"] = 0, ["y"] = 0, ["param1"] = 0, ["z"] = 10, ["name"] = "default:wood" }, { ["x"] = 0, ["meta"] = { ["fields"] = {  }, ["inventory"] = {  } }, ["param2"] = 0, ["y"] = 0, ["param1"] = 0, ["z"] = 11, ["name"] = "default:wood" }, { ["x"] = 0, ["meta"] = { ["fields"] = {  }, ["inventory"] = {  } }, ["param2"] = 0, ["y"] = 0, ["param1"] = 0, ["z"] = 12, ["name"] = "default:wood" }, { ["x"] = 0, ["meta"] = { ["fields"] = {  }, ["inventory"] = {  } }, ["param2"] = 0, ["y"] = 1, ["param1"] = 0, ["z"] = 1, ["name"] = "default:wood" }, { ["x"] = 0, ["meta"] = { ["fields"] = {  }, ["inventory"] = {  } }, ["param2"] = 0, ["y"] = 1, ["param1"] = 0, ["z"] = 2, ["name"] = "default:wood" }, { ["x"] = 0, ["meta"] = { ["fields"] = {  }, ["inventory"] = {  } }, ["param2"] = 0, ["y"] = 1, ["param1"] = 0, ["z"] = 3, ["name"] = "default:wood" }, { ["x"] = 0, ["meta"] = { ["fields"] = {  }, ["inventory"] = {  } }, ["param2"] = 0, ["y"] = 1, ["param1"] = 0, ["z"] = 4, ["name"] = "default:wood" }, { ["x"] = 0, ["meta"] = { ["fields"] = {  }, ["inventory"] = {  } }, ["param2"] = 0, ["y"] = 1, ["param1"] = 0, ["z"] = 5, ["name"] = "default:wood" }, { ["x"] = 0, ["meta"] = { ["fields"] = {  }, ["inventory"] = {  } }, ["param2"] = 0, ["y"] = 1, ["param1"] = 0, ["z"] = 6, ["name"] = "default:wood" }, { ["x"] = 0, ["meta"] = { ["fields"] = {  }, ["inventory"] = {  } }, ["param2"] = 0, ["y"] = 1, ["param1"] = 0, ["z"] = 7, ["name"] = "default:wood" }, { ["x"] = 0, ["meta"] = { ["fields"] = {  }, ["inventory"] = {  } }, ["param2"] = 0, ["y"] = 1, ["param1"] = 0, ["z"] = 8, ["name"] = "default:wood" }, { ["x"] = 0, ["meta"] = { ["fields"] = {  }, ["inventory"] = {  } }, ["param2"] = 0, ["y"] = 1, ["param1"] = 0, ["z"] = 9, ["name"] = "default:wood" }, { ["x"] = 0, ["meta"] = { ["fields"] = {  }, ["inventory"] = {  } }, ["param2"] = 0, ["y"] = 1, ["param1"] = 0, ["z"] = 10, ["name"] = "default:wood" }, { ["x"] = 0, ["meta"] = { ["fields"] = {  }, ["inventory"] = {  } }, ["param2"] = 0, ["y"] = 1, ["param1"] = 0, ["z"] = 11, ["name"] = "default:wood" }, { ["x"] = 0, ["meta"] = { ["fields"] = {  }, ["inventory"] = {  } }, ["param2"] = 0, ["y"] = 1, ["param1"] = 0, ["z"] = 12, ["name"] = "default:wood" }, { ["x"] = 0, ["meta"] = { ["fields"] = {  }, ["inventory"] = {  } }, ["param2"] = 0, ["y"] = 2, ["param1"] = 0, ["z"] = 1, ["name"] = "default:wood" }, { ["x"] = 0, ["meta"] = { ["fields"] = {  }, ["inventory"] = {  } }, ["param2"] = 0, ["y"] = 2, ["param1"] = 0, ["z"] = 2, ["name"] = "default:wood" }, { ["x"] = 0, ["meta"] = { ["fields"] = {  }, ["inventory"] = {  } }, ["param2"] = 0, ["y"] = 2, ["param1"] = 0, ["z"] = 3, ["name"] = "default:wood" }, { ["x"] = 0, ["meta"] = { ["fields"] = {  }, ["inventory"] = {  } }, ["param2"] = 0, ["y"] = 2, ["param1"] = 0, ["z"] = 4, ["name"] = "default:wood" }, { ["x"] = 0, ["meta"] = { ["fields"] = {  }, ["inventory"] = {  } }, ["param2"] = 0, ["y"] = 2, ["param1"] = 0, ["z"] = 5, ["name"] = "default:wood" }, { ["x"] = 0, ["meta"] = { ["fields"] = {  }, ["inventory"] = {  } }, ["param2"] = 0, ["y"] = 2, ["param1"] = 0, ["z"] = 6, ["name"] = "default:wood" }, { ["x"] = 0, ["meta"] = { ["fields"] = {  }, ["inventory"] = {  } }, ["param2"] = 0, ["y"] = 2, ["param1"] = 0, ["z"] = 7, ["name"] = "default:wood" }, { ["x"] = 0, ["meta"] = { ["fields"] = {  }, ["inventory"] = {  } }, ["param2"] = 0, ["y"] = 2, ["param1"] = 0, ["z"] = 8, ["name"] = "default:wood" }, { ["x"] = 0, ["meta"] = { ["fields"] = {  }, ["inventory"] = {  } }, ["param2"] = 0, ["y"] = 2, ["param1"] = 0, ["z"] = 9, ["name"] = "default:wood" }, { ["x"] = 0, ["meta"] = { ["fields"] = {  }, ["inventory"] = {  } }, ["param2"] = 0, ["y"] = 2, ["param1"] = 0, ["z"] = 10, ["name"] = "default:wood" }, { ["x"] = 0, ["meta"] = { ["fields"] = {  }, ["inventory"] = {  } }, ["param2"] = 0, ["y"] = 2, ["param1"] = 0, ["z"] = 11, ["name"] = "default:wood" }, { ["x"] = 0, ["meta"] = { ["fields"] = {  }, ["inventory"] = {  } }, ["param2"] = 0, ["y"] = 2, ["param1"] = 0, ["z"] = 12, ["name"] = "default:wood" }, { ["x"] = 0, ["meta"] = { ["fields"] = {  }, ["inventory"] = {  } }, ["param2"] = 0, ["y"] = 3, ["param1"] = 141, ["z"] = 1, ["name"] = "stairs:slab_wood" }, { ["x"] = 0, ["meta"] = { ["fields"] = {  }, ["inventory"] = {  } }, ["param2"] = 1, ["y"] = 3, ["param1"] = 157, ["z"] = 2, ["name"] = "stairs:stair_wood" }, { ["x"] = 0, ["meta"] = { ["fields"] = {  }, ["inventory"] = {  } }, ["param2"] = 1, ["y"] = 3, ["param1"] = 173, ["z"] = 3, ["name"] = "stairs:stair_wood" }, { ["x"] = 0, ["meta"] = { ["fields"] = {  }, ["inventory"] = {  } }, ["param2"] = 1, ["y"] = 3, ["param1"] = 157, ["z"] = 4, ["name"] = "stairs:stair_wood" }, { ["x"] = 0, ["meta"] = { ["fields"] = {  }, ["inventory"] = {  } }, ["param2"] = 1, ["y"] = 3, ["param1"] = 157, ["z"] = 5, ["name"] = "stairs:stair_wood" }, { ["x"] = 0, ["meta"] = { ["fields"] = {  }, ["inventory"] = {  } }, ["param2"] = 1, ["y"] = 3, ["param1"] = 141, ["z"] = 6, ["name"] = "stairs:stair_wood" }, { ["x"] = 0, ["meta"] = { ["fields"] = {  }, ["inventory"] = {  } }, ["param2"] = 1, ["y"] = 3, ["param1"] = 157, ["z"] = 7, ["name"] = "stairs:stair_wood" }, { ["x"] = 0, ["meta"] = { ["fields"] = {  }, ["inventory"] = {  } }, ["param2"] = 1, ["y"] = 3, ["param1"] = 173, ["z"] = 8, ["name"] = "stairs:stair_wood" }, { ["x"] = 0, ["meta"] = { ["fields"] = {  }, ["inventory"] = {  } }, ["param2"] = 1, ["y"] = 3, ["param1"] = 157, ["z"] = 9, ["name"] = "stairs:stair_wood" }, { ["x"] = 0, ["meta"] = { ["fields"] = {  }, ["inventory"] = {  } }, ["param2"] = 1, ["y"] = 3, ["param1"] = 173, ["z"] = 10, ["name"] = "stairs:stair_wood" }, { ["x"] = 0, ["meta"] = { ["fields"] = {  }, ["inventory"] = {  } }, ["param2"] = 1, ["y"] = 3, ["param1"] = 157, ["z"] = 11, ["name"] = "stairs:stair_wood" }, { ["x"] = 0, ["meta"] = { ["fields"] = {  }, ["inventory"] = {  } }, ["param2"] = 0, ["y"] = 3, ["param1"] = 141, ["z"] = 12, ["name"] = "stairs:slab_wood" }, { ["x"] = 1, ["meta"] = { ["fields"] = {  }, ["inventory"] = {  } }, ["param2"] = 0, ["y"] = 0, ["param1"] = 0, ["z"] = 1, ["name"] = "default:wood" }, { ["x"] = 1, ["meta"] = { ["fields"] = {  }, ["inventory"] = {  } }, ["param2"] = 0, ["y"] = 0, ["param1"] = 0, ["z"] = 2, ["name"] = "default:wood" }, { ["x"] = 1, ["meta"] = { ["fields"] = {  }, ["inventory"] = {  } }, ["param2"] = 0, ["y"] = 0, ["param1"] = 0, ["z"] = 3, ["name"] = "default:wood" }, { ["x"] = 1, ["meta"] = { ["fields"] = {  }, ["inventory"] = {  } }, ["param2"] = 0, ["y"] = 0, ["param1"] = 0, ["z"] = 4, ["name"] = "default:wood" }, { ["x"] = 1, ["meta"] = { ["fields"] = {  }, ["inventory"] = {  } }, ["param2"] = 0, ["y"] = 0, ["param1"] = 0, ["z"] = 5, ["name"] = "default:wood" }, { ["x"] = 1, ["meta"] = { ["fields"] = {  }, ["inventory"] = {  } }, ["param2"] = 0, ["y"] = 0, ["param1"] = 15, ["z"] = 6, ["name"] = "default:wood" }, { ["x"] = 1, ["meta"] = { ["fields"] = {  }, ["inventory"] = {  } }, ["param2"] = 0, ["y"] = 0, ["param1"] = 15, ["z"] = 7, ["name"] = "default:wood" }, { ["x"] = 1, ["meta"] = { ["fields"] = {  }, ["inventory"] = {  } }, ["param2"] = 0, ["y"] = 0, ["param1"] = 15, ["z"] = 8, ["name"] = "default:wood" }, { ["x"] = 1, ["meta"] = { ["fields"] = {  }, ["inventory"] = {  } }, ["param2"] = 0, ["y"] = 0, ["param1"] = 15, ["z"] = 9, ["name"] = "default:wood" }, { ["x"] = 1, ["meta"] = { ["fields"] = {  }, ["inventory"] = {  } }, ["param2"] = 0, ["y"] = 0, ["param1"] = 15, ["z"] = 10, ["name"] = "default:wood" }, { ["x"] = 1, ["meta"] = { ["fields"] = {  }, ["inventory"] = {  } }, ["param2"] = 0, ["y"] = 0, ["param1"] = 15, ["z"] = 11, ["name"] = "default:wood" }, { ["x"] = 1, ["meta"] = { ["fields"] = {  }, ["inventory"] = {  } }, ["param2"] = 0, ["y"] = 0, ["param1"] = 15, ["z"] = 12, ["name"] = "default:wood" }, { ["x"] = 1, ["meta"] = { ["fields"] = {  }, ["inventory"] = {  } }, ["param2"] = 0, ["y"] = 1, ["param1"] = 0, ["z"] = 1, ["name"] = "default:wood" }, { ["x"] = 1, ["meta"] = { ["fields"] = {  }, ["inventory"] = {  } }, ["param2"] = 0, ["y"] = 1, ["param1"] = 0, ["z"] = 2, ["name"] = "default:bookshelf" }, { ["x"] = 1, ["meta"] = { ["fields"] = {  }, ["inventory"] = {  } }, ["param2"] = 0, ["y"] = 1, ["param1"] = 0, ["z"] = 3, ["name"] = "default:bookshelf" }, { ["x"] = 1, ["meta"] = { ["fields"] = {  }, ["inventory"] = {  } }, ["param2"] = 0, ["y"] = 1, ["param1"] = 0, ["z"] = 4, ["name"] = "default:bookshelf" }, { ["x"] = 1, ["meta"] = { ["fields"] = {  }, ["inventory"] = {  } }, ["param2"] = 0, ["y"] = 1, ["param1"] = 0, ["z"] = 5, ["name"] = "default:bookshelf" }, { ["x"] = 1, ["meta"] = { ["fields"] = {  }, ["inventory"] = {  } }, ["param2"] = 0, ["y"] = 1, ["param1"] = 0, ["z"] = 6, ["name"] = "default:bookshelf" }, { ["x"] = 1, ["meta"] = { ["fields"] = {  }, ["inventory"] = {  } }, ["param2"] = 0, ["y"] = 1, ["param1"] = 0, ["z"] = 7, ["name"] = "default:bookshelf" }, { ["x"] = 1, ["meta"] = { ["fields"] = {  }, ["inventory"] = {  } }, ["param2"] = 0, ["y"] = 1, ["param1"] = 0, ["z"] = 8, ["name"] = "default:bookshelf" }, { ["x"] = 1, ["meta"] = { ["fields"] = {  }, ["inventory"] = {  } }, ["param2"] = 0, ["y"] = 1, ["param1"] = 0, ["z"] = 9, ["name"] = "default:bookshelf" }, { ["x"] = 1, ["meta"] = { ["fields"] = {  }, ["inventory"] = {  } }, ["param2"] = 0, ["y"] = 1, ["param1"] = 0, ["z"] = 10, ["name"] = "default:bookshelf" }, { ["x"] = 1, ["meta"] = { ["fields"] = {  }, ["inventory"] = {  } }, ["param2"] = 0, ["y"] = 1, ["param1"] = 0, ["z"] = 11, ["name"] = "default:bookshelf" }, { ["x"] = 1, ["meta"] = { ["fields"] = {  }, ["inventory"] = {  } }, ["param2"] = 0, ["y"] = 1, ["param1"] = 0, ["z"] = 12, ["name"] = "default:wood" }, { ["x"] = 1, ["meta"] = { ["fields"] = {  }, ["inventory"] = {  } }, ["param2"] = 0, ["y"] = 2, ["param1"] = 0, ["z"] = 1, ["name"] = "default:wood" }, { ["x"] = 1, ["meta"] = { ["fields"] = {  }, ["inventory"] = {  } }, ["param2"] = 0, ["y"] = 2, ["param1"] = 0, ["z"] = 2, ["name"] = "default:bookshelf" }, { ["x"] = 1, ["meta"] = { ["fields"] = {  }, ["inventory"] = {  } }, ["param2"] = 0, ["y"] = 2, ["param1"] = 0, ["z"] = 3, ["name"] = "default:bookshelf" }, { ["x"] = 1, ["meta"] = { ["fields"] = {  }, ["inventory"] = {  } }, ["param2"] = 0, ["y"] = 2, ["param1"] = 0, ["z"] = 4, ["name"] = "default:bookshelf" }, { ["x"] = 1, ["meta"] = { ["fields"] = {  }, ["inventory"] = {  } }, ["param2"] = 0, ["y"] = 2, ["param1"] = 0, ["z"] = 5, ["name"] = "default:bookshelf" }, { ["x"] = 1, ["meta"] = { ["fields"] = {  }, ["inventory"] = {  } }, ["param2"] = 0, ["y"] = 2, ["param1"] = 0, ["z"] = 6, ["name"] = "default:bookshelf" }, { ["x"] = 1, ["meta"] = { ["fields"] = {  }, ["inventory"] = {  } }, ["param2"] = 0, ["y"] = 2, ["param1"] = 0, ["z"] = 7, ["name"] = "default:bookshelf" }, { ["x"] = 1, ["meta"] = { ["fields"] = {  }, ["inventory"] = {  } }, ["param2"] = 0, ["y"] = 2, ["param1"] = 0, ["z"] = 8, ["name"] = "default:bookshelf" }, { ["x"] = 1, ["meta"] = { ["fields"] = {  }, ["inventory"] = {  } }, ["param2"] = 0, ["y"] = 2, ["param1"] = 0, ["z"] = 9, ["name"] = "default:bookshelf" }, { ["x"] = 1, ["meta"] = { ["fields"] = {  }, ["inventory"] = {  } }, ["param2"] = 0, ["y"] = 2, ["param1"] = 0, ["z"] = 10, ["name"] = "default:bookshelf" }, { ["x"] = 1, ["meta"] = { ["fields"] = {  }, ["inventory"] = {  } }, ["param2"] = 0, ["y"] = 2, ["param1"] = 0, ["z"] = 11, ["name"] = "default:bookshelf" }, { ["x"] = 1, ["meta"] = { ["fields"] = {  }, ["inventory"] = {  } }, ["param2"] = 0, ["y"] = 2, ["param1"] = 0, ["z"] = 12, ["name"] = "default:wood" }, { ["x"] = 1, ["meta"] = { ["fields"] = {  }, ["inventory"] = {  } }, ["param2"] = 0, ["y"] = 3, ["param1"] = 157, ["z"] = 1, ["name"] = "stairs:stair_wood" }, { ["x"] = 1, ["meta"] = { ["fields"] = {  }, ["inventory"] = {  } }, ["param2"] = 0, ["y"] = 3, ["param1"] = 0, ["z"] = 2, ["name"] = "default:bookshelf" }, { ["x"] = 1, ["meta"] = { ["fields"] = {  }, ["inventory"] = {  } }, ["param2"] = 0, ["y"] = 3, ["param1"] = 0, ["z"] = 3, ["name"] = "default:bookshelf" }, { ["x"] = 1, ["meta"] = { ["fields"] = {  }, ["inventory"] = {  } }, ["param2"] = 0, ["y"] = 3, ["param1"] = 0, ["z"] = 4, ["name"] = "default:bookshelf" }, { ["x"] = 1, ["meta"] = { ["fields"] = {  }, ["inventory"] = {  } }, ["param2"] = 0, ["y"] = 3, ["param1"] = 0, ["z"] = 5, ["name"] = "default:bookshelf" }, { ["x"] = 1, ["meta"] = { ["fields"] = {  }, ["inventory"] = {  } }, ["param2"] = 0, ["y"] = 3, ["param1"] = 0, ["z"] = 6, ["name"] = "default:bookshelf" }, { ["x"] = 1, ["meta"] = { ["fields"] = {  }, ["inventory"] = {  } }, ["param2"] = 0, ["y"] = 3, ["param1"] = 0, ["z"] = 7, ["name"] = "default:bookshelf" }, { ["x"] = 1, ["meta"] = { ["fields"] = {  }, ["inventory"] = {  } }, ["param2"] = 0, ["y"] = 3, ["param1"] = 0, ["z"] = 8, ["name"] = "default:bookshelf" }, { ["x"] = 1, ["meta"] = { ["fields"] = {  }, ["inventory"] = {  } }, ["param2"] = 0, ["y"] = 3, ["param1"] = 0, ["z"] = 9, ["name"] = "default:bookshelf" }, { ["x"] = 1, ["meta"] = { ["fields"] = {  }, ["inventory"] = {  } }, ["param2"] = 0, ["y"] = 3, ["param1"] = 0, ["z"] = 10, ["name"] = "default:bookshelf" }, { ["x"] = 1, ["meta"] = { ["fields"] = {  }, ["inventory"] = {  } }, ["param2"] = 0, ["y"] = 3, ["param1"] = 0, ["z"] = 11, ["name"] = "default:bookshelf" }, { ["x"] = 1, ["meta"] = { ["fields"] = {  }, ["inventory"] = {  } }, ["param2"] = 2, ["y"] = 3, ["param1"] = 157, ["z"] = 12, ["name"] = "stairs:stair_wood" }, { ["x"] = 1, ["meta"] = { ["fields"] = {  }, ["inventory"] = {  } }, ["param2"] = 0, ["y"] = 4, ["param1"] = 189, ["z"] = 2, ["name"] = "stairs:slab_wood" }, { ["x"] = 1, ["meta"] = { ["fields"] = {  }, ["inventory"] = {  } }, ["param2"] = 1, ["y"] = 4, ["param1"] = 205, ["z"] = 3, ["name"] = "stairs:stair_wood" }, { ["x"] = 1, ["meta"] = { ["fields"] = {  }, ["inventory"] = {  } }, ["param2"] = 1, ["y"] = 4, ["param1"] = 189, ["z"] = 4, ["name"] = "stairs:stair_wood" }, { ["x"] = 1, ["meta"] = { ["fields"] = {  }, ["inventory"] = {  } }, ["param2"] = 1, ["y"] = 4, ["param1"] = 189, ["z"] = 5, ["name"] = "stairs:stair_wood" }, { ["x"] = 1, ["meta"] = { ["fields"] = {  }, ["inventory"] = {  } }, ["param2"] = 1, ["y"] = 4, ["param1"] = 173, ["z"] = 6, ["name"] = "stairs:stair_wood" }, { ["x"] = 1, ["meta"] = { ["fields"] = {  }, ["inventory"] = {  } }, ["param2"] = 1, ["y"] = 4, ["param1"] = 189, ["z"] = 7, ["name"] = "stairs:stair_wood" }, { ["x"] = 1, ["meta"] = { ["fields"] = {  }, ["inventory"] = {  } }, ["param2"] = 1, ["y"] = 4, ["param1"] = 205, ["z"] = 8, ["name"] = "stairs:stair_wood" }, { ["x"] = 1, ["meta"] = { ["fields"] = {  }, ["inventory"] = {  } }, ["param2"] = 1, ["y"] = 4, ["param1"] = 189, ["z"] = 9, ["name"] = "stairs:stair_wood" }, { ["x"] = 1, ["meta"] = { ["fields"] = {  }, ["inventory"] = {  } }, ["param2"] = 1, ["y"] = 4, ["param1"] = 205, ["z"] = 10, ["name"] = "stairs:stair_wood" }, { ["x"] = 1, ["meta"] = { ["fields"] = {  }, ["inventory"] = {  } }, ["param2"] = 0, ["y"] = 4, ["param1"] = 189, ["z"] = 11, ["name"] = "stairs:slab_wood" }, { ["x"] = 2, ["meta"] = { ["fields"] = {  }, ["inventory"] = {  } }, ["param2"] = 0, ["y"] = 0, ["param1"] = 0, ["z"] = 1, ["name"] = "default:wood" }, { ["x"] = 2, ["meta"] = { ["fields"] = {  }, ["inventory"] = {  } }, ["param2"] = 0, ["y"] = 0, ["param1"] = 0, ["z"] = 2, ["name"] = "default:wood" }, { ["x"] = 2, ["meta"] = { ["fields"] = {  }, ["inventory"] = {  } }, ["param2"] = 0, ["y"] = 0, ["param1"] = 0, ["z"] = 3, ["name"] = "default:wood" }, { ["x"] = 2, ["meta"] = { ["fields"] = {  }, ["inventory"] = {  } }, ["param2"] = 0, ["y"] = 0, ["param1"] = 0, ["z"] = 4, ["name"] = "default:wood" }, { ["x"] = 2, ["meta"] = { ["fields"] = {  }, ["inventory"] = {  } }, ["param2"] = 0, ["y"] = 0, ["param1"] = 0, ["z"] = 5, ["name"] = "default:wood" }, { ["x"] = 2, ["meta"] = { ["fields"] = {  }, ["inventory"] = {  } }, ["param2"] = 0, ["y"] = 0, ["param1"] = 15, ["z"] = 6, ["name"] = "default:wood" }, { ["x"] = 2, ["meta"] = { ["fields"] = {  }, ["inventory"] = {  } }, ["param2"] = 0, ["y"] = 0, ["param1"] = 15, ["z"] = 7, ["name"] = "default:wood" }, { ["x"] = 2, ["meta"] = { ["fields"] = {  }, ["inventory"] = {  } }, ["param2"] = 0, ["y"] = 0, ["param1"] = 15, ["z"] = 8, ["name"] = "default:wood" }, { ["x"] = 2, ["meta"] = { ["fields"] = {  }, ["inventory"] = {  } }, ["param2"] = 0, ["y"] = 0, ["param1"] = 15, ["z"] = 9, ["name"] = "default:wood" }, { ["x"] = 2, ["meta"] = { ["fields"] = {  }, ["inventory"] = {  } }, ["param2"] = 0, ["y"] = 0, ["param1"] = 15, ["z"] = 10, ["name"] = "default:wood" }, { ["x"] = 2, ["meta"] = { ["fields"] = {  }, ["inventory"] = {  } }, ["param2"] = 0, ["y"] = 0, ["param1"] = 15, ["z"] = 11, ["name"] = "default:wood" }, { ["x"] = 2, ["meta"] = { ["fields"] = {  }, ["inventory"] = {  } }, ["param2"] = 0, ["y"] = 0, ["param1"] = 15, ["z"] = 12, ["name"] = "default:wood" }, { ["x"] = 2, ["meta"] = { ["fields"] = {  }, ["inventory"] = {  } }, ["param2"] = 0, ["y"] = 1, ["param1"] = 0, ["z"] = 1, ["name"] = "default:wood" }, { ["x"] = 2, ["meta"] = { ["fields"] = {  }, ["inventory"] = {  } }, ["param2"] = 0, ["y"] = 1, ["param1"] = 0, ["z"] = 2, ["name"] = "default:bookshelf" }, { ["x"] = 2, ["meta"] = { ["fields"] = {  }, ["inventory"] = {  } }, ["param2"] = 0, ["y"] = 1, ["param1"] = 0, ["z"] = 11, ["name"] = "default:bookshelf" }, { ["x"] = 2, ["meta"] = { ["fields"] = {  }, ["inventory"] = {  } }, ["param2"] = 0, ["y"] = 1, ["param1"] = 0, ["z"] = 12, ["name"] = "default:wood" }, { ["x"] = 2, ["meta"] = { ["fields"] = {  }, ["inventory"] = {  } }, ["param2"] = 0, ["y"] = 2, ["param1"] = 0, ["z"] = 1, ["name"] = "default:wood" }, { ["x"] = 2, ["meta"] = { ["fields"] = {  }, ["inventory"] = {  } }, ["param2"] = 0, ["y"] = 2, ["param1"] = 0, ["z"] = 2, ["name"] = "default:bookshelf" }, { ["x"] = 2, ["meta"] = { ["fields"] = {  }, ["inventory"] = {  } }, ["param2"] = 0, ["y"] = 2, ["param1"] = 0, ["z"] = 11, ["name"] = "default:bookshelf" }, { ["x"] = 2, ["meta"] = { ["fields"] = {  }, ["inventory"] = {  } }, ["param2"] = 0, ["y"] = 2, ["param1"] = 0, ["z"] = 12, ["name"] = "default:wood" }, { ["x"] = 2, ["meta"] = { ["fields"] = {  }, ["inventory"] = {  } }, ["param2"] = 0, ["y"] = 3, ["param1"] = 173, ["z"] = 1, ["name"] = "stairs:stair_wood" }, { ["x"] = 2, ["meta"] = { ["fields"] = {  }, ["inventory"] = {  } }, ["param2"] = 0, ["y"] = 3, ["param1"] = 0, ["z"] = 2, ["name"] = "default:bookshelf" }, { ["x"] = 2, ["meta"] = { ["fields"] = {  }, ["inventory"] = {  } }, ["param2"] = 0, ["y"] = 3, ["param1"] = 0, ["z"] = 11, ["name"] = "default:bookshelf" }, { ["x"] = 2, ["meta"] = { ["fields"] = {  }, ["inventory"] = {  } }, ["param2"] = 2, ["y"] = 3, ["param1"] = 173, ["z"] = 12, ["name"] = "stairs:stair_wood" }, { ["x"] = 2, ["meta"] = { ["fields"] = {  }, ["inventory"] = {  } }, ["param2"] = 0, ["y"] = 4, ["param1"] = 205, ["z"] = 2, ["name"] = "stairs:stair_wood" }, { ["x"] = 2, ["meta"] = { ["fields"] = {  }, ["inventory"] = {  } }, ["param2"] = 5, ["y"] = 4, ["param1"] = 0, ["z"] = 3, ["name"] = "default:torch" }, { ["x"] = 2, ["meta"] = { ["fields"] = {  }, ["inventory"] = {  } }, ["param2"] = 2, ["y"] = 4, ["param1"] = 0, ["z"] = 8, ["name"] = "default:torch" }, { ["x"] = 2, ["meta"] = { ["fields"] = {  }, ["inventory"] = {  } }, ["param2"] = 4, ["y"] = 4, ["param1"] = 0, ["z"] = 10, ["name"] = "default:torch" }, { ["x"] = 2, ["meta"] = { ["fields"] = {  }, ["inventory"] = {  } }, ["param2"] = 2, ["y"] = 4, ["param1"] = 205, ["z"] = 11, ["name"] = "stairs:stair_wood" }, { ["x"] = 2, ["meta"] = { ["fields"] = {  }, ["inventory"] = {  } }, ["param2"] = 0, ["y"] = 5, ["param1"] = 205, ["z"] = 3, ["name"] = "stairs:slab_wood" }, { ["x"] = 2, ["meta"] = { ["fields"] = {  }, ["inventory"] = {  } }, ["param2"] = 0, ["y"] = 5, ["param1"] = 189, ["z"] = 4, ["name"] = "stairs:slab_wood" }, { ["x"] = 2, ["meta"] = { ["fields"] = {  }, ["inventory"] = {  } }, ["param2"] = 0, ["y"] = 5, ["param1"] = 189, ["z"] = 5, ["name"] = "stairs:slab_wood" }, { ["x"] = 2, ["meta"] = { ["fields"] = {  }, ["inventory"] = {  } }, ["param2"] = 0, ["y"] = 5, ["param1"] = 173, ["z"] = 6, ["name"] = "stairs:slab_wood" }, { ["x"] = 2, ["meta"] = { ["fields"] = {  }, ["inventory"] = {  } }, ["param2"] = 0, ["y"] = 5, ["param1"] = 189, ["z"] = 7, ["name"] = "stairs:slab_wood" }, { ["x"] = 2, ["meta"] = { ["fields"] = {  }, ["inventory"] = {  } }, ["param2"] = 0, ["y"] = 5, ["param1"] = 205, ["z"] = 8, ["name"] = "stairs:slab_wood" }, { ["x"] = 2, ["meta"] = { ["fields"] = {  }, ["inventory"] = {  } }, ["param2"] = 0, ["y"] = 5, ["param1"] = 189, ["z"] = 9, ["name"] = "stairs:slab_wood" }, { ["x"] = 2, ["meta"] = { ["fields"] = {  }, ["inventory"] = {  } }, ["param2"] = 0, ["y"] = 5, ["param1"] = 205, ["z"] = 10, ["name"] = "stairs:slab_wood" }, { ["x"] = 3, ["meta"] = { ["fields"] = {  }, ["inventory"] = {  } }, ["param2"] = 0, ["y"] = 0, ["param1"] = 0, ["z"] = 1, ["name"] = "default:wood" }, { ["x"] = 3, ["meta"] = { ["fields"] = {  }, ["inventory"] = {  } }, ["param2"] = 0, ["y"] = 0, ["param1"] = 0, ["z"] = 2, ["name"] = "default:wood" }, { ["x"] = 3, ["meta"] = { ["fields"] = {  }, ["inventory"] = {  } }, ["param2"] = 0, ["y"] = 0, ["param1"] = 0, ["z"] = 3, ["name"] = "default:wood" }, { ["x"] = 3, ["meta"] = { ["fields"] = {  }, ["inventory"] = {  } }, ["param2"] = 0, ["y"] = 0, ["param1"] = 0, ["z"] = 4, ["name"] = "default:wood" }, { ["x"] = 3, ["meta"] = { ["fields"] = {  }, ["inventory"] = {  } }, ["param2"] = 0, ["y"] = 0, ["param1"] = 0, ["z"] = 5, ["name"] = "default:wood" }, { ["x"] = 3, ["meta"] = { ["fields"] = {  }, ["inventory"] = {  } }, ["param2"] = 0, ["y"] = 0, ["param1"] = 15, ["z"] = 6, ["name"] = "default:wood" }, { ["x"] = 3, ["meta"] = { ["fields"] = {  }, ["inventory"] = {  } }, ["param2"] = 0, ["y"] = 0, ["param1"] = 15, ["z"] = 7, ["name"] = "default:wood" }, { ["x"] = 3, ["meta"] = { ["fields"] = {  }, ["inventory"] = {  } }, ["param2"] = 0, ["y"] = 0, ["param1"] = 15, ["z"] = 8, ["name"] = "default:wood" }, { ["x"] = 3, ["meta"] = { ["fields"] = {  }, ["inventory"] = {  } }, ["param2"] = 0, ["y"] = 0, ["param1"] = 15, ["z"] = 9, ["name"] = "default:wood" }, { ["x"] = 3, ["meta"] = { ["fields"] = {  }, ["inventory"] = {  } }, ["param2"] = 0, ["y"] = 0, ["param1"] = 15, ["z"] = 10, ["name"] = "default:wood" }, { ["x"] = 3, ["meta"] = { ["fields"] = {  }, ["inventory"] = {  } }, ["param2"] = 0, ["y"] = 0, ["param1"] = 15, ["z"] = 11, ["name"] = "default:wood" }, { ["x"] = 3, ["meta"] = { ["fields"] = {  }, ["inventory"] = {  } }, ["param2"] = 0, ["y"] = 0, ["param1"] = 15, ["z"] = 12, ["name"] = "default:wood" }, { ["x"] = 3, ["meta"] = { ["fields"] = {  }, ["inventory"] = {  } }, ["param2"] = 0, ["y"] = 1, ["param1"] = 0, ["z"] = 1, ["name"] = "default:wood" }, { ["x"] = 3, ["meta"] = { ["fields"] = {  }, ["inventory"] = {  } }, ["param2"] = 0, ["y"] = 1, ["param1"] = 0, ["z"] = 2, ["name"] = "default:bookshelf" }, { ["x"] = 3, ["meta"] = { ["fields"] = {  }, ["inventory"] = {  } }, ["param2"] = 0, ["y"] = 1, ["param1"] = 0, ["z"] = 6, ["name"] = "default:bookshelf" }, { ["x"] = 3, ["meta"] = { ["fields"] = {  }, ["inventory"] = {  } }, ["param2"] = 0, ["y"] = 1, ["param1"] = 0, ["z"] = 7, ["name"] = "default:bookshelf" }, { ["x"] = 3, ["meta"] = { ["fields"] = {  }, ["inventory"] = {  } }, ["param2"] = 0, ["y"] = 1, ["param1"] = 0, ["z"] = 8, ["name"] = "default:bookshelf" }, { ["x"] = 3, ["meta"] = { ["fields"] = {  }, ["inventory"] = {  } }, ["param2"] = 0, ["y"] = 1, ["param1"] = 0, ["z"] = 9, ["name"] = "default:bookshelf" }, { ["x"] = 3, ["meta"] = { ["fields"] = {  }, ["inventory"] = {  } }, ["param2"] = 0, ["y"] = 1, ["param1"] = 0, ["z"] = 10, ["name"] = "default:bookshelf" }, { ["x"] = 3, ["meta"] = { ["fields"] = {  }, ["inventory"] = {  } }, ["param2"] = 0, ["y"] = 1, ["param1"] = 0, ["z"] = 11, ["name"] = "default:bookshelf" }, { ["x"] = 3, ["meta"] = { ["fields"] = {  }, ["inventory"] = {  } }, ["param2"] = 0, ["y"] = 1, ["param1"] = 0, ["z"] = 12, ["name"] = "default:wood" }, { ["x"] = 3, ["meta"] = { ["fields"] = {  }, ["inventory"] = {  } }, ["param2"] = 0, ["y"] = 2, ["param1"] = 0, ["z"] = 1, ["name"] = "default:wood" }, { ["x"] = 3, ["meta"] = { ["fields"] = {  }, ["inventory"] = {  } }, ["param2"] = 0, ["y"] = 2, ["param1"] = 0, ["z"] = 2, ["name"] = "default:bookshelf" }, { ["x"] = 3, ["meta"] = { ["fields"] = {  }, ["inventory"] = {  } }, ["param2"] = 0, ["y"] = 2, ["param1"] = 0, ["z"] = 6, ["name"] = "default:bookshelf" }, { ["x"] = 3, ["meta"] = { ["fields"] = {  }, ["inventory"] = {  } }, ["param2"] = 0, ["y"] = 2, ["param1"] = 0, ["z"] = 7, ["name"] = "default:bookshelf" }, { ["x"] = 3, ["meta"] = { ["fields"] = {  }, ["inventory"] = {  } }, ["param2"] = 0, ["y"] = 2, ["param1"] = 0, ["z"] = 8, ["name"] = "default:bookshelf" }, { ["x"] = 3, ["meta"] = { ["fields"] = {  }, ["inventory"] = {  } }, ["param2"] = 0, ["y"] = 2, ["param1"] = 0, ["z"] = 9, ["name"] = "default:bookshelf" }, { ["x"] = 3, ["meta"] = { ["fields"] = {  }, ["inventory"] = {  } }, ["param2"] = 0, ["y"] = 2, ["param1"] = 0, ["z"] = 10, ["name"] = "default:bookshelf" }, { ["x"] = 3, ["meta"] = { ["fields"] = {  }, ["inventory"] = {  } }, ["param2"] = 0, ["y"] = 2, ["param1"] = 0, ["z"] = 11, ["name"] = "default:bookshelf" }, { ["x"] = 3, ["meta"] = { ["fields"] = {  }, ["inventory"] = {  } }, ["param2"] = 0, ["y"] = 2, ["param1"] = 0, ["z"] = 12, ["name"] = "default:wood" }, { ["x"] = 3, ["meta"] = { ["fields"] = {  }, ["inventory"] = {  } }, ["param2"] = 0, ["y"] = 3, ["param1"] = 173, ["z"] = 1, ["name"] = "stairs:stair_wood" }, { ["x"] = 3, ["meta"] = { ["fields"] = {  }, ["inventory"] = {  } }, ["param2"] = 0, ["y"] = 3, ["param1"] = 0, ["z"] = 2, ["name"] = "default:bookshelf" }, { ["x"] = 3, ["meta"] = { ["fields"] = {  }, ["inventory"] = {  } }, ["param2"] = 0, ["y"] = 3, ["param1"] = 0, ["z"] = 6, ["name"] = "default:bookshelf" }, { ["x"] = 3, ["meta"] = { ["fields"] = {  }, ["inventory"] = {  } }, ["param2"] = 0, ["y"] = 3, ["param1"] = 0, ["z"] = 7, ["name"] = "default:bookshelf" }, { ["x"] = 3, ["meta"] = { ["fields"] = {  }, ["inventory"] = {  } }, ["param2"] = 0, ["y"] = 3, ["param1"] = 0, ["z"] = 8, ["name"] = "default:bookshelf" }, { ["x"] = 3, ["meta"] = { ["fields"] = {  }, ["inventory"] = {  } }, ["param2"] = 0, ["y"] = 3, ["param1"] = 0, ["z"] = 9, ["name"] = "default:bookshelf" }, { ["x"] = 3, ["meta"] = { ["fields"] = {  }, ["inventory"] = {  } }, ["param2"] = 0, ["y"] = 3, ["param1"] = 0, ["z"] = 10, ["name"] = "default:bookshelf" }, { ["x"] = 3, ["meta"] = { ["fields"] = {  }, ["inventory"] = {  } }, ["param2"] = 0, ["y"] = 3, ["param1"] = 0, ["z"] = 11, ["name"] = "default:bookshelf" }, { ["x"] = 3, ["meta"] = { ["fields"] = {  }, ["inventory"] = {  } }, ["param2"] = 2, ["y"] = 3, ["param1"] = 157, ["z"] = 12, ["name"] = "stairs:stair_wood" }, { ["x"] = 3, ["meta"] = { ["fields"] = {  }, ["inventory"] = {  } }, ["param2"] = 0, ["y"] = 4, ["param1"] = 189, ["z"] = 2, ["name"] = "stairs:stair_wood" }, { ["x"] = 3, ["meta"] = { ["fields"] = {  }, ["inventory"] = {  } }, ["param2"] = 4, ["y"] = 4, ["param1"] = 0, ["z"] = 5, ["name"] = "default:torch" }, { ["x"] = 3, ["meta"] = { ["fields"] = {  }, ["inventory"] = {  } }, ["param2"] = 0, ["y"] = 4, ["param1"] = 0, ["z"] = 6, ["name"] = "default:wood" }, { ["x"] = 3, ["meta"] = { ["fields"] = {  }, ["inventory"] = {  } }, ["param2"] = 3, ["y"] = 4, ["param1"] = 189, ["z"] = 7, ["name"] = "stairs:stair_wood" }, { ["x"] = 3, ["meta"] = { ["fields"] = {  }, ["inventory"] = {  } }, ["param2"] = 3, ["y"] = 4, ["param1"] = 205, ["z"] = 8, ["name"] = "stairs:stair_wood" }, { ["x"] = 3, ["meta"] = { ["fields"] = {  }, ["inventory"] = {  } }, ["param2"] = 3, ["y"] = 4, ["param1"] = 189, ["z"] = 9, ["name"] = "stairs:stair_wood" }, { ["x"] = 3, ["meta"] = { ["fields"] = {  }, ["inventory"] = {  } }, ["param2"] = 3, ["y"] = 4, ["param1"] = 205, ["z"] = 10, ["name"] = "stairs:stair_wood" }, { ["x"] = 3, ["meta"] = { ["fields"] = {  }, ["inventory"] = {  } }, ["param2"] = 0, ["y"] = 4, ["param1"] = 189, ["z"] = 11, ["name"] = "stairs:slab_wood" }, { ["x"] = 3, ["meta"] = { ["fields"] = {  }, ["inventory"] = {  } }, ["param2"] = 0, ["y"] = 5, ["param1"] = 189, ["z"] = 3, ["name"] = "stairs:slab_wood" }, { ["x"] = 3, ["meta"] = { ["fields"] = {  }, ["inventory"] = {  } }, ["param2"] = 0, ["y"] = 5, ["param1"] = 189, ["z"] = 4, ["name"] = "stairs:slab_wood" }, { ["x"] = 3, ["meta"] = { ["fields"] = {  }, ["inventory"] = {  } }, ["param2"] = 0, ["y"] = 5, ["param1"] = 205, ["z"] = 5, ["name"] = "stairs:slab_wood" }, { ["x"] = 4, ["meta"] = { ["fields"] = {  }, ["inventory"] = {  } }, ["param2"] = 0, ["y"] = 0, ["param1"] = 0, ["z"] = 1, ["name"] = "default:wood" }, { ["x"] = 4, ["meta"] = { ["fields"] = {  }, ["inventory"] = {  } }, ["param2"] = 0, ["y"] = 0, ["param1"] = 0, ["z"] = 2, ["name"] = "default:wood" }, { ["x"] = 4, ["meta"] = { ["fields"] = {  }, ["inventory"] = {  } }, ["param2"] = 0, ["y"] = 0, ["param1"] = 0, ["z"] = 3, ["name"] = "default:wood" }, { ["x"] = 4, ["meta"] = { ["fields"] = {  }, ["inventory"] = {  } }, ["param2"] = 0, ["y"] = 0, ["param1"] = 0, ["z"] = 4, ["name"] = "default:wood" }, { ["x"] = 4, ["meta"] = { ["fields"] = {  }, ["inventory"] = {  } }, ["param2"] = 0, ["y"] = 0, ["param1"] = 0, ["z"] = 5, ["name"] = "default:wood" }, { ["x"] = 4, ["meta"] = { ["fields"] = {  }, ["inventory"] = {  } }, ["param2"] = 0, ["y"] = 0, ["param1"] = 15, ["z"] = 6, ["name"] = "default:wood" }, { ["x"] = 4, ["meta"] = { ["fields"] = {  }, ["inventory"] = {  } }, ["param2"] = 0, ["y"] = 0, ["param1"] = 15, ["z"] = 7, ["name"] = "default:wood" }, { ["x"] = 4, ["meta"] = { ["fields"] = {  }, ["inventory"] = {  } }, ["param2"] = 0, ["y"] = 0, ["param1"] = 15, ["z"] = 8, ["name"] = "default:wood" }, { ["x"] = 4, ["meta"] = { ["fields"] = {  }, ["inventory"] = {  } }, ["param2"] = 0, ["y"] = 0, ["param1"] = 15, ["z"] = 9, ["name"] = "default:wood" }, { ["x"] = 4, ["meta"] = { ["fields"] = {  }, ["inventory"] = {  } }, ["param2"] = 0, ["y"] = 0, ["param1"] = 15, ["z"] = 10, ["name"] = "default:wood" }, { ["x"] = 4, ["meta"] = { ["fields"] = {  }, ["inventory"] = {  } }, ["param2"] = 0, ["y"] = 0, ["param1"] = 15, ["z"] = 11, ["name"] = "default:wood" }, { ["x"] = 4, ["meta"] = { ["fields"] = {  }, ["inventory"] = {  } }, ["param2"] = 0, ["y"] = 0, ["param1"] = 15, ["z"] = 12, ["name"] = "default:wood" }, { ["x"] = 4, ["meta"] = { ["fields"] = {  }, ["inventory"] = {  } }, ["param2"] = 0, ["y"] = 1, ["param1"] = 0, ["z"] = 1, ["name"] = "default:wood" }, { ["x"] = 4, ["meta"] = { ["fields"] = {  }, ["inventory"] = {  } }, ["param2"] = 0, ["y"] = 1, ["param1"] = 0, ["z"] = 2, ["name"] = "default:bookshelf" }, { ["x"] = 4, ["meta"] = { ["fields"] = {  }, ["inventory"] = {  } }, ["param2"] = 0, ["y"] = 1, ["param1"] = 0, ["z"] = 6, ["name"] = "default:bookshelf" }, { ["x"] = 4, ["meta"] = { ["fields"] = {  }, ["inventory"] = {  } }, ["param2"] = 0, ["y"] = 1, ["param1"] = 0, ["z"] = 7, ["name"] = "default:wood" }, { ["x"] = 4, ["meta"] = { ["fields"] = {  }, ["inventory"] = {  } }, ["param2"] = 0, ["y"] = 1, ["param1"] = 0, ["z"] = 8, ["name"] = "default:wood" }, { ["x"] = 4, ["meta"] = { ["fields"] = {  }, ["inventory"] = {  } }, ["param2"] = 0, ["y"] = 1, ["param1"] = 0, ["z"] = 9, ["name"] = "default:wood" }, { ["x"] = 4, ["meta"] = { ["fields"] = {  }, ["inventory"] = {  } }, ["param2"] = 0, ["y"] = 1, ["param1"] = 0, ["z"] = 10, ["name"] = "default:wood" }, { ["x"] = 4, ["meta"] = { ["fields"] = {  }, ["inventory"] = {  } }, ["param2"] = 0, ["y"] = 1, ["param1"] = 0, ["z"] = 11, ["name"] = "default:wood" }, { ["x"] = 4, ["meta"] = { ["fields"] = {  }, ["inventory"] = {  } }, ["param2"] = 0, ["y"] = 1, ["param1"] = 0, ["z"] = 12, ["name"] = "default:wood" }, { ["x"] = 4, ["meta"] = { ["fields"] = {  }, ["inventory"] = {  } }, ["param2"] = 4, ["y"] = 2, ["param1"] = 15, ["z"] = 0, ["name"] = "default:torch" }, { ["x"] = 4, ["meta"] = { ["fields"] = {  }, ["inventory"] = {  } }, ["param2"] = 0, ["y"] = 2, ["param1"] = 0, ["z"] = 1, ["name"] = "default:wood" }, { ["x"] = 4, ["meta"] = { ["fields"] = {  }, ["inventory"] = {  } }, ["param2"] = 0, ["y"] = 2, ["param1"] = 0, ["z"] = 2, ["name"] = "default:bookshelf" }, { ["x"] = 4, ["meta"] = { ["fields"] = {  }, ["inventory"] = {  } }, ["param2"] = 0, ["y"] = 2, ["param1"] = 0, ["z"] = 6, ["name"] = "default:bookshelf" }, { ["x"] = 4, ["meta"] = { ["fields"] = {  }, ["inventory"] = {  } }, ["param2"] = 0, ["y"] = 2, ["param1"] = 0, ["z"] = 7, ["name"] = "default:wood" }, { ["x"] = 4, ["meta"] = { ["fields"] = {  }, ["inventory"] = {  } }, ["param2"] = 0, ["y"] = 2, ["param1"] = 0, ["z"] = 8, ["name"] = "default:wood" }, { ["x"] = 4, ["meta"] = { ["fields"] = {  }, ["inventory"] = {  } }, ["param2"] = 0, ["y"] = 2, ["param1"] = 0, ["z"] = 9, ["name"] = "default:wood" }, { ["x"] = 4, ["meta"] = { ["fields"] = {  }, ["inventory"] = {  } }, ["param2"] = 0, ["y"] = 2, ["param1"] = 0, ["z"] = 10, ["name"] = "default:wood" }, { ["x"] = 4, ["meta"] = { ["fields"] = {  }, ["inventory"] = {  } }, ["param2"] = 0, ["y"] = 2, ["param1"] = 0, ["z"] = 11, ["name"] = "default:wood" }, { ["x"] = 4, ["meta"] = { ["fields"] = {  }, ["inventory"] = {  } }, ["param2"] = 0, ["y"] = 2, ["param1"] = 0, ["z"] = 12, ["name"] = "default:wood" }, { ["x"] = 4, ["meta"] = { ["fields"] = {  }, ["inventory"] = {  } }, ["param2"] = 0, ["y"] = 3, ["param1"] = 189, ["z"] = 1, ["name"] = "stairs:stair_wood" }, { ["x"] = 4, ["meta"] = { ["fields"] = {  }, ["inventory"] = {  } }, ["param2"] = 0, ["y"] = 3, ["param1"] = 0, ["z"] = 2, ["name"] = "default:bookshelf" }, { ["x"] = 4, ["meta"] = { ["fields"] = {  }, ["inventory"] = {  } }, ["param2"] = 0, ["y"] = 3, ["param1"] = 0, ["z"] = 6, ["name"] = "default:bookshelf" }, { ["x"] = 4, ["meta"] = { ["fields"] = {  }, ["inventory"] = {  } }, ["param2"] = 0, ["y"] = 3, ["param1"] = 0, ["z"] = 7, ["name"] = "default:wood" }, { ["x"] = 4, ["meta"] = { ["fields"] = {  }, ["inventory"] = {  } }, ["param2"] = 3, ["y"] = 3, ["param1"] = 173, ["z"] = 8, ["name"] = "stairs:stair_wood" }, { ["x"] = 4, ["meta"] = { ["fields"] = {  }, ["inventory"] = {  } }, ["param2"] = 3, ["y"] = 3, ["param1"] = 157, ["z"] = 9, ["name"] = "stairs:stair_wood" }, { ["x"] = 4, ["meta"] = { ["fields"] = {  }, ["inventory"] = {  } }, ["param2"] = 3, ["y"] = 3, ["param1"] = 173, ["z"] = 10, ["name"] = "stairs:stair_wood" }, { ["x"] = 4, ["meta"] = { ["fields"] = {  }, ["inventory"] = {  } }, ["param2"] = 3, ["y"] = 3, ["param1"] = 157, ["z"] = 11, ["name"] = "stairs:stair_wood" }, { ["x"] = 4, ["meta"] = { ["fields"] = {  }, ["inventory"] = {  } }, ["param2"] = 0, ["y"] = 3, ["param1"] = 141, ["z"] = 12, ["name"] = "stairs:slab_wood" }, { ["x"] = 4, ["meta"] = { ["fields"] = {  }, ["inventory"] = {  } }, ["param2"] = 0, ["y"] = 4, ["param1"] = 189, ["z"] = 2, ["name"] = "stairs:stair_wood" }, { ["x"] = 4, ["meta"] = { ["fields"] = {  }, ["inventory"] = {  } }, ["param2"] = 2, ["y"] = 4, ["param1"] = 189, ["z"] = 6, ["name"] = "stairs:stair_wood" }, { ["x"] = 4, ["meta"] = { ["fields"] = {  }, ["inventory"] = {  } }, ["param2"] = 0, ["y"] = 5, ["param1"] = 189, ["z"] = 3, ["name"] = "stairs:slab_wood" }, { ["x"] = 4, ["meta"] = { ["fields"] = {  }, ["inventory"] = {  } }, ["param2"] = 0, ["y"] = 5, ["param1"] = 173, ["z"] = 4, ["name"] = "stairs:slab_wood" }, { ["x"] = 4, ["meta"] = { ["fields"] = {  }, ["inventory"] = {  } }, ["param2"] = 0, ["y"] = 5, ["param1"] = 189, ["z"] = 5, ["name"] = "stairs:slab_wood" }, { ["x"] = 5, ["meta"] = { ["fields"] = {  }, ["inventory"] = {  } }, ["param2"] = 0, ["y"] = 0, ["param1"] = 0, ["z"] = 1, ["name"] = "default:wood" }, { ["x"] = 5, ["meta"] = { ["fields"] = {  }, ["inventory"] = {  } }, ["param2"] = 0, ["y"] = 0, ["param1"] = 0, ["z"] = 2, ["name"] = "default:wood" }, { ["x"] = 5, ["meta"] = { ["fields"] = {  }, ["inventory"] = {  } }, ["param2"] = 0, ["y"] = 0, ["param1"] = 0, ["z"] = 3, ["name"] = "default:wood" }, { ["x"] = 5, ["meta"] = { ["fields"] = {  }, ["inventory"] = {  } }, ["param2"] = 0, ["y"] = 0, ["param1"] = 0, ["z"] = 4, ["name"] = "default:wood" }, { ["x"] = 5, ["meta"] = { ["fields"] = {  }, ["inventory"] = {  } }, ["param2"] = 0, ["y"] = 0, ["param1"] = 0, ["z"] = 5, ["name"] = "default:wood" }, { ["x"] = 5, ["meta"] = { ["fields"] = {  }, ["inventory"] = {  } }, ["param2"] = 0, ["y"] = 0, ["param1"] = 15, ["z"] = 6, ["name"] = "default:wood" }, { ["x"] = 5, ["meta"] = { ["fields"] = {  }, ["inventory"] = {  } }, ["param2"] = 0, ["y"] = 0, ["param1"] = 15, ["z"] = 7, ["name"] = "default:wood" }, { ["x"] = 5, ["meta"] = { ["fields"] = {  }, ["inventory"] = {  } }, ["param2"] = 0, ["y"] = 1, ["param1"] = 173, ["z"] = 1, ["name"] = "doors:door_wood_b_1" }, { ["x"] = 5, ["meta"] = { ["fields"] = {  }, ["inventory"] = {  } }, ["param2"] = 0, ["y"] = 1, ["param1"] = 0, ["z"] = 6, ["name"] = "default:bookshelf" }, { ["x"] = 5, ["meta"] = { ["fields"] = {  }, ["inventory"] = {  } }, ["param2"] = 0, ["y"] = 1, ["param1"] = 0, ["z"] = 7, ["name"] = "default:wood" }, { ["x"] = 5, ["meta"] = { ["fields"] = {  }, ["inventory"] = {  } }, ["param2"] = 0, ["y"] = 2, ["param1"] = 189, ["z"] = 1, ["name"] = "doors:door_wood_t_1" }, { ["x"] = 5, ["meta"] = { ["fields"] = {  }, ["inventory"] = {  } }, ["param2"] = 0, ["y"] = 2, ["param1"] = 0, ["z"] = 6, ["name"] = "default:bookshelf" }, { ["x"] = 5, ["meta"] = { ["fields"] = {  }, ["inventory"] = {  } }, ["param2"] = 0, ["y"] = 2, ["param1"] = 0, ["z"] = 7, ["name"] = "default:wood" }, { ["x"] = 5, ["meta"] = { ["fields"] = {  }, ["inventory"] = {  } }, ["param2"] = 4, ["y"] = 3, ["param1"] = 15, ["z"] = 0, ["name"] = "default:torch" }, { ["x"] = 5, ["meta"] = { ["fields"] = {  }, ["inventory"] = {  } }, ["param2"] = 0, ["y"] = 3, ["param1"] = 205, ["z"] = 1, ["name"] = "stairs:stair_wood" }, { ["x"] = 5, ["meta"] = { ["fields"] = {  }, ["inventory"] = {  } }, ["param2"] = 5, ["y"] = 3, ["param1"] = 0, ["z"] = 2, ["name"] = "default:torch" }, { ["x"] = 5, ["meta"] = { ["fields"] = {  }, ["inventory"] = {  } }, ["param2"] = 0, ["y"] = 3, ["param1"] = 0, ["z"] = 6, ["name"] = "default:bookshelf" }, { ["x"] = 5, ["meta"] = { ["fields"] = {  }, ["inventory"] = {  } }, ["param2"] = 2, ["y"] = 3, ["param1"] = 157, ["z"] = 7, ["name"] = "stairs:stair_wood" }, { ["x"] = 5, ["meta"] = { ["fields"] = {  }, ["inventory"] = {  } }, ["param2"] = 0, ["y"] = 4, ["param1"] = 205, ["z"] = 2, ["name"] = "stairs:stair_wood" }, { ["x"] = 5, ["meta"] = { ["fields"] = {  }, ["inventory"] = {  } }, ["param2"] = 2, ["y"] = 4, ["param1"] = 0, ["z"] = 3, ["name"] = "default:torch" }, { ["x"] = 5, ["meta"] = { ["fields"] = {  }, ["inventory"] = {  } }, ["param2"] = 2, ["y"] = 4, ["param1"] = 173, ["z"] = 6, ["name"] = "stairs:stair_wood" }, { ["x"] = 5, ["meta"] = { ["fields"] = {  }, ["inventory"] = {  } }, ["param2"] = 0, ["y"] = 5, ["param1"] = 205, ["z"] = 3, ["name"] = "stairs:slab_wood" }, { ["x"] = 5, ["meta"] = { ["fields"] = {  }, ["inventory"] = {  } }, ["param2"] = 0, ["y"] = 5, ["param1"] = 189, ["z"] = 4, ["name"] = "stairs:slab_wood" }, { ["x"] = 5, ["meta"] = { ["fields"] = {  }, ["inventory"] = {  } }, ["param2"] = 0, ["y"] = 5, ["param1"] = 173, ["z"] = 5, ["name"] = "stairs:slab_wood" }, { ["x"] = 6, ["meta"] = { ["fields"] = {  }, ["inventory"] = {  } }, ["param2"] = 0, ["y"] = 0, ["param1"] = 95, ["z"] = 1, ["name"] = "default:wood" }, { ["x"] = 6, ["meta"] = { ["fields"] = {  }, ["inventory"] = {  } }, ["param2"] = 0, ["y"] = 0, ["param1"] = 77, ["z"] = 2, ["name"] = "default:wood" }, { ["x"] = 6, ["meta"] = { ["fields"] = {  }, ["inventory"] = {  } }, ["param2"] = 0, ["y"] = 0, ["param1"] = 63, ["z"] = 3, ["name"] = "default:wood" }, { ["x"] = 6, ["meta"] = { ["fields"] = {  }, ["inventory"] = {  } }, ["param2"] = 0, ["y"] = 0, ["param1"] = 45, ["z"] = 4, ["name"] = "default:wood" }, { ["x"] = 6, ["meta"] = { ["fields"] = {  }, ["inventory"] = {  } }, ["param2"] = 0, ["y"] = 0, ["param1"] = 31, ["z"] = 5, ["name"] = "default:wood" }, { ["x"] = 6, ["meta"] = { ["fields"] = {  }, ["inventory"] = {  } }, ["param2"] = 0, ["y"] = 0, ["param1"] = 15, ["z"] = 6, ["name"] = "default:wood" }, { ["x"] = 6, ["meta"] = { ["fields"] = {  }, ["inventory"] = {  } }, ["param2"] = 0, ["y"] = 0, ["param1"] = 15, ["z"] = 7, ["name"] = "default:wood" }, { ["x"] = 6, ["meta"] = { ["fields"] = {  }, ["inventory"] = {  } }, ["param2"] = 0, ["y"] = 1, ["param1"] = 0, ["z"] = 1, ["name"] = "default:wood" }, { ["x"] = 6, ["meta"] = { ["fields"] = {  }, ["inventory"] = {  } }, ["param2"] = 0, ["y"] = 1, ["param1"] = 0, ["z"] = 2, ["name"] = "default:bookshelf" }, { ["x"] = 6, ["meta"] = { ["fields"] = {  }, ["inventory"] = {  } }, ["param2"] = 0, ["y"] = 1, ["param1"] = 0, ["z"] = 6, ["name"] = "default:bookshelf" }, { ["x"] = 6, ["meta"] = { ["fields"] = {  }, ["inventory"] = {  } }, ["param2"] = 0, ["y"] = 1, ["param1"] = 0, ["z"] = 7, ["name"] = "default:wood" }, { ["x"] = 6, ["meta"] = { ["fields"] = {  }, ["inventory"] = {  } }, ["param2"] = 4, ["y"] = 2, ["param1"] = 15, ["z"] = 0, ["name"] = "default:torch" }, { ["x"] = 6, ["meta"] = { ["fields"] = {  }, ["inventory"] = {  } }, ["param2"] = 0, ["y"] = 2, ["param1"] = 0, ["z"] = 1, ["name"] = "default:wood" }, { ["x"] = 6, ["meta"] = { ["fields"] = {  }, ["inventory"] = {  } }, ["param2"] = 0, ["y"] = 2, ["param1"] = 0, ["z"] = 2, ["name"] = "default:bookshelf" }, { ["x"] = 6, ["meta"] = { ["fields"] = {  }, ["inventory"] = {  } }, ["param2"] = 0, ["y"] = 2, ["param1"] = 0, ["z"] = 6, ["name"] = "default:bookshelf" }, { ["x"] = 6, ["meta"] = { ["fields"] = {  }, ["inventory"] = {  } }, ["param2"] = 0, ["y"] = 2, ["param1"] = 0, ["z"] = 7, ["name"] = "default:wood" }, { ["x"] = 6, ["meta"] = { ["fields"] = {  }, ["inventory"] = {  } }, ["param2"] = 0, ["y"] = 3, ["param1"] = 189, ["z"] = 1, ["name"] = "stairs:stair_wood" }, { ["x"] = 6, ["meta"] = { ["fields"] = {  }, ["inventory"] = {  } }, ["param2"] = 0, ["y"] = 3, ["param1"] = 0, ["z"] = 2, ["name"] = "default:bookshelf" }, { ["x"] = 6, ["meta"] = { ["fields"] = {  }, ["inventory"] = {  } }, ["param2"] = 0, ["y"] = 3, ["param1"] = 0, ["z"] = 6, ["name"] = "default:bookshelf" }, { ["x"] = 6, ["meta"] = { ["fields"] = {  }, ["inventory"] = {  } }, ["param2"] = 2, ["y"] = 3, ["param1"] = 173, ["z"] = 7, ["name"] = "stairs:stair_wood" }, { ["x"] = 6, ["meta"] = { ["fields"] = {  }, ["inventory"] = {  } }, ["param2"] = 0, ["y"] = 4, ["param1"] = 189, ["z"] = 2, ["name"] = "stairs:slab_wood" }, { ["x"] = 6, ["meta"] = { ["fields"] = {  }, ["inventory"] = {  } }, ["param2"] = 3, ["y"] = 4, ["param1"] = 205, ["z"] = 3, ["name"] = "stairs:stair_wood" }, { ["x"] = 6, ["meta"] = { ["fields"] = {  }, ["inventory"] = {  } }, ["param2"] = 3, ["y"] = 4, ["param1"] = 189, ["z"] = 4, ["name"] = "stairs:stair_wood" }, { ["x"] = 6, ["meta"] = { ["fields"] = {  }, ["inventory"] = {  } }, ["param2"] = 3, ["y"] = 4, ["param1"] = 173, ["z"] = 5, ["name"] = "stairs:stair_wood" }, { ["x"] = 6, ["meta"] = { ["fields"] = {  }, ["inventory"] = {  } }, ["param2"] = 0, ["y"] = 4, ["param1"] = 173, ["z"] = 6, ["name"] = "stairs:slab_wood" }, { ["x"] = 7, ["meta"] = { ["fields"] = {  }, ["inventory"] = {  } }, ["param2"] = 0, ["y"] = 0, ["param1"] = 111, ["z"] = 1, ["name"] = "default:wood" }, { ["x"] = 7, ["meta"] = { ["fields"] = {  }, ["inventory"] = {  } }, ["param2"] = 0, ["y"] = 0, ["param1"] = 95, ["z"] = 2, ["name"] = "default:wood" }, { ["x"] = 7, ["meta"] = { ["fields"] = {  }, ["inventory"] = {  } }, ["param2"] = 0, ["y"] = 0, ["param1"] = 79, ["z"] = 3, ["name"] = "default:wood" }, { ["x"] = 7, ["meta"] = { ["fields"] = {  }, ["inventory"] = {  } }, ["param2"] = 0, ["y"] = 0, ["param1"] = 63, ["z"] = 4, ["name"] = "default:wood" }, { ["x"] = 7, ["meta"] = { ["fields"] = {  }, ["inventory"] = {  } }, ["param2"] = 0, ["y"] = 0, ["param1"] = 45, ["z"] = 5, ["name"] = "default:wood" }, { ["x"] = 7, ["meta"] = { ["fields"] = {  }, ["inventory"] = {  } }, ["param2"] = 0, ["y"] = 0, ["param1"] = 29, ["z"] = 6, ["name"] = "default:wood" }, { ["x"] = 7, ["meta"] = { ["fields"] = {  }, ["inventory"] = {  } }, ["param2"] = 0, ["y"] = 0, ["param1"] = 15, ["z"] = 7, ["name"] = "default:wood" }, { ["x"] = 7, ["meta"] = { ["fields"] = {  }, ["inventory"] = {  } }, ["param2"] = 0, ["y"] = 1, ["param1"] = 0, ["z"] = 1, ["name"] = "default:wood" }, { ["x"] = 7, ["meta"] = { ["fields"] = {  }, ["inventory"] = {  } }, ["param2"] = 0, ["y"] = 1, ["param1"] = 0, ["z"] = 2, ["name"] = "default:wood" }, { ["x"] = 7, ["meta"] = { ["fields"] = {  }, ["inventory"] = {  } }, ["param2"] = 0, ["y"] = 1, ["param1"] = 0, ["z"] = 3, ["name"] = "default:wood" }, { ["x"] = 7, ["meta"] = { ["fields"] = {  }, ["inventory"] = {  } }, ["param2"] = 1, ["y"] = 1, ["param1"] = 170, ["z"] = 4, ["name"] = "doors:door_wood_b_1" }, { ["x"] = 7, ["meta"] = { ["fields"] = {  }, ["inventory"] = {  } }, ["param2"] = 0, ["y"] = 1, ["param1"] = 0, ["z"] = 5, ["name"] = "default:wood" }, { ["x"] = 7, ["meta"] = { ["fields"] = {  }, ["inventory"] = {  } }, ["param2"] = 0, ["y"] = 1, ["param1"] = 0, ["z"] = 6, ["name"] = "default:wood" }, { ["x"] = 7, ["meta"] = { ["fields"] = {  }, ["inventory"] = {  } }, ["param2"] = 0, ["y"] = 1, ["param1"] = 0, ["z"] = 7, ["name"] = "default:wood" }, { ["x"] = 7, ["meta"] = { ["fields"] = {  }, ["inventory"] = {  } }, ["param2"] = 0, ["y"] = 2, ["param1"] = 0, ["z"] = 1, ["name"] = "default:wood" }, { ["x"] = 7, ["meta"] = { ["fields"] = {  }, ["inventory"] = {  } }, ["param2"] = 0, ["y"] = 2, ["param1"] = 0, ["z"] = 2, ["name"] = "default:wood" }, { ["x"] = 7, ["meta"] = { ["fields"] = {  }, ["inventory"] = {  } }, ["param2"] = 0, ["y"] = 2, ["param1"] = 0, ["z"] = 3, ["name"] = "default:wood" }, { ["x"] = 7, ["meta"] = { ["fields"] = {  }, ["inventory"] = {  } }, ["param2"] = 1, ["y"] = 2, ["param1"] = 187, ["z"] = 4, ["name"] = "doors:door_wood_t_1" }, { ["x"] = 7, ["meta"] = { ["fields"] = {  }, ["inventory"] = {  } }, ["param2"] = 0, ["y"] = 2, ["param1"] = 0, ["z"] = 5, ["name"] = "default:wood" }, { ["x"] = 7, ["meta"] = { ["fields"] = {  }, ["inventory"] = {  } }, ["param2"] = 0, ["y"] = 2, ["param1"] = 0, ["z"] = 6, ["name"] = "default:wood" }, { ["x"] = 7, ["meta"] = { ["fields"] = {  }, ["inventory"] = {  } }, ["param2"] = 0, ["y"] = 2, ["param1"] = 0, ["z"] = 7, ["name"] = "default:wood" }, { ["x"] = 7, ["meta"] = { ["fields"] = {  }, ["inventory"] = {  } }, ["param2"] = 0, ["y"] = 3, ["param1"] = 173, ["z"] = 1, ["name"] = "stairs:stair_wood" }, { ["x"] = 7, ["meta"] = { ["fields"] = {  }, ["inventory"] = {  } }, ["param2"] = 0, ["y"] = 3, ["param1"] = 0, ["z"] = 2, ["name"] = "default:wood" }, { ["x"] = 7, ["meta"] = { ["fields"] = {  }, ["inventory"] = {  } }, ["param2"] = 0, ["y"] = 3, ["param1"] = 0, ["z"] = 3, ["name"] = "default:wood" }, { ["x"] = 7, ["meta"] = { ["fields"] = {  }, ["inventory"] = {  } }, ["param2"] = 0, ["y"] = 3, ["param1"] = 0, ["z"] = 4, ["name"] = "default:wood" }, { ["x"] = 7, ["meta"] = { ["fields"] = {  }, ["inventory"] = {  } }, ["param2"] = 0, ["y"] = 3, ["param1"] = 0, ["z"] = 5, ["name"] = "default:wood" }, { ["x"] = 7, ["meta"] = { ["fields"] = {  }, ["inventory"] = {  } }, ["param2"] = 0, ["y"] = 3, ["param1"] = 0, ["z"] = 6, ["name"] = "default:wood" }, { ["x"] = 7, ["meta"] = { ["fields"] = {  }, ["inventory"] = {  } }, ["param2"] = 2, ["y"] = 3, ["param1"] = 189, ["z"] = 7, ["name"] = "stairs:stair_wood" }, { ["x"] = 7, ["meta"] = { ["fields"] = {  }, ["inventory"] = {  } }, ["param2"] = 0, ["y"] = 4, ["param1"] = 173, ["z"] = 2, ["name"] = "stairs:slab_wood" }, { ["x"] = 7, ["meta"] = { ["fields"] = {  }, ["inventory"] = {  } }, ["param2"] = 0, ["y"] = 4, ["param1"] = 189, ["z"] = 3, ["name"] = "stairs:slab_wood" }, { ["x"] = 7, ["meta"] = { ["fields"] = {  }, ["inventory"] = {  } }, ["param2"] = 0, ["y"] = 4, ["param1"] = 189, ["z"] = 4, ["name"] = "stairs:slab_wood" }, { ["x"] = 7, ["meta"] = { ["fields"] = {  }, ["inventory"] = {  } }, ["param2"] = 0, ["y"] = 4, ["param1"] = 173, ["z"] = 5, ["name"] = "stairs:slab_wood" }, { ["x"] = 7, ["meta"] = { ["fields"] = {  }, ["inventory"] = {  } }, ["param2"] = 0, ["y"] = 4, ["param1"] = 189, ["z"] = 6, ["name"] = "stairs:slab_wood" }, { ["x"] = 8, ["meta"] = { ["fields"] = {  }, ["inventory"] = {  } }, ["param2"] = 0, ["y"] = 0, ["param1"] = 125, ["z"] = 1, ["name"] = "default:wood" }, { ["x"] = 8, ["meta"] = { ["fields"] = {  }, ["inventory"] = {  } }, ["param2"] = 0, ["y"] = 0, ["param1"] = 111, ["z"] = 2, ["name"] = "default:wood" }, { ["x"] = 8, ["meta"] = { ["fields"] = {  }, ["inventory"] = {  } }, ["param2"] = 0, ["y"] = 0, ["param1"] = 93, ["z"] = 3, ["name"] = "default:wood" }, { ["x"] = 8, ["meta"] = { ["fields"] = {  }, ["inventory"] = {  } }, ["param2"] = 0, ["y"] = 0, ["param1"] = 77, ["z"] = 4, ["name"] = "default:wood" }, { ["x"] = 8, ["meta"] = { ["fields"] = {  }, ["inventory"] = {  } }, ["param2"] = 0, ["y"] = 0, ["param1"] = 63, ["z"] = 5, ["name"] = "default:wood" }, { ["x"] = 8, ["meta"] = { ["fields"] = {  }, ["inventory"] = {  } }, ["param2"] = 0, ["y"] = 0, ["param1"] = 47, ["z"] = 6, ["name"] = "default:wood" }, { ["x"] = 8, ["meta"] = { ["fields"] = {  }, ["inventory"] = {  } }, ["param2"] = 0, ["y"] = 0, ["param1"] = 31, ["z"] = 7, ["name"] = "default:wood" }, { ["x"] = 8, ["meta"] = { ["fields"] = {  }, ["inventory"] = {  } }, ["param2"] = 0, ["y"] = 1, ["param1"] = 0, ["z"] = 1, ["name"] = "default:wood" }, { ["x"] = 8, ["meta"] = { ["fields"] = { ["infotext"] = "Chest", ["formspec"] = "size[8,9]list[current_name;main;0,0;8,4;]list[current_player;main;0,5;8,4;]" }, ["inventory"] = { ["main"] = { "default:bookshelf 256", "default:bookshelf 256", "default:bookshelf 256", "default:bookshelf 512", "default:bookshelf 512", "default:bookshelf 512", "", "", "default:paper 256", "default:paper 512", "default:paper 512", "", "", "", "", "", "default:papyrus 256", "default:papyrus 512", "default:papyrus 512", "", "", "", "", "", "", "", "", "", "", "", "", "" } } }, ["param2"] = 2, ["y"] = 1, ["param1"] = 0, ["z"] = 2, ["name"] = "default:npc_chest" }, { ["x"] = 8, ["meta"] = { ["fields"] = {  }, ["inventory"] = {  } }, ["param2"] = 0, ["y"] = 1, ["param1"] = 187, ["z"] = 6, ["name"] = "stairs:stair_wood" }, { ["x"] = 8, ["meta"] = { ["fields"] = {  }, ["inventory"] = {  } }, ["param2"] = 0, ["y"] = 1, ["param1"] = 0, ["z"] = 7, ["name"] = "default:wood" }, { ["x"] = 8, ["meta"] = { ["fields"] = {  }, ["inventory"] = {  } }, ["param2"] = 0, ["y"] = 2, ["param1"] = 0, ["z"] = 1, ["name"] = "default:wood" }, { ["x"] = 8, ["meta"] = { ["fields"] = {  }, ["inventory"] = {  } }, ["param2"] = 0, ["y"] = 2, ["param1"] = 0, ["z"] = 7, ["name"] = "default:wood" }, { ["x"] = 8, ["meta"] = { ["fields"] = {  }, ["inventory"] = {  } }, ["param2"] = 0, ["y"] = 3, ["param1"] = 189, ["z"] = 1, ["name"] = "stairs:stair_wood" }, { ["x"] = 8, ["meta"] = { ["fields"] = {  }, ["inventory"] = {  } }, ["param2"] = 3, ["y"] = 3, ["param1"] = 0, ["z"] = 4, ["name"] = "default:torch" }, { ["x"] = 8, ["meta"] = { ["fields"] = {  }, ["inventory"] = {  } }, ["param2"] = 4, ["y"] = 3, ["param1"] = 0, ["z"] = 6, ["name"] = "default:torch" }, { ["x"] = 8, ["meta"] = { ["fields"] = {  }, ["inventory"] = {  } }, ["param2"] = 2, ["y"] = 3, ["param1"] = 205, ["z"] = 7, ["name"] = "stairs:stair_wood" }, { ["x"] = 8, ["meta"] = { ["fields"] = {  }, ["inventory"] = {  } }, ["param2"] = 0, ["y"] = 4, ["param1"] = 189, ["z"] = 2, ["name"] = "stairs:slab_wood" }, { ["x"] = 8, ["meta"] = { ["fields"] = {  }, ["inventory"] = {  } }, ["param2"] = 0, ["y"] = 4, ["param1"] = 189, ["z"] = 3, ["name"] = "stairs:slab_wood" }, { ["x"] = 8, ["meta"] = { ["fields"] = {  }, ["inventory"] = {  } }, ["param2"] = 0, ["y"] = 4, ["param1"] = 205, ["z"] = 4, ["name"] = "stairs:slab_wood" }, { ["x"] = 8, ["meta"] = { ["fields"] = {  }, ["inventory"] = {  } }, ["param2"] = 0, ["y"] = 4, ["param1"] = 189, ["z"] = 5, ["name"] = "stairs:slab_wood" }, { ["x"] = 8, ["meta"] = { ["fields"] = {  }, ["inventory"] = {  } }, ["param2"] = 0, ["y"] = 4, ["param1"] = 205, ["z"] = 6, ["name"] = "stairs:slab_wood" }, { ["x"] = 9, ["meta"] = { ["fields"] = {  }, ["inventory"] = {  } }, ["param2"] = 0, ["y"] = 0, ["param1"] = 109, ["z"] = 1, ["name"] = "default:wood" }, { ["x"] = 9, ["meta"] = { ["fields"] = {  }, ["inventory"] = {  } }, ["param2"] = 0, ["y"] = 0, ["param1"] = 95, ["z"] = 2, ["name"] = "default:wood" }, { ["x"] = 9, ["meta"] = { ["fields"] = {  }, ["inventory"] = {  } }, ["param2"] = 0, ["y"] = 0, ["param1"] = 79, ["z"] = 3, ["name"] = "default:wood" }, { ["x"] = 9, ["meta"] = { ["fields"] = {  }, ["inventory"] = {  } }, ["param2"] = 0, ["y"] = 0, ["param1"] = 63, ["z"] = 4, ["name"] = "default:wood" }, { ["x"] = 9, ["meta"] = { ["fields"] = {  }, ["inventory"] = {  } }, ["param2"] = 0, ["y"] = 0, ["param1"] = 47, ["z"] = 5, ["name"] = "default:wood" }, { ["x"] = 9, ["meta"] = { ["fields"] = {  }, ["inventory"] = {  } }, ["param2"] = 0, ["y"] = 0, ["param1"] = 31, ["z"] = 6, ["name"] = "default:wood" }, { ["x"] = 9, ["meta"] = { ["fields"] = {  }, ["inventory"] = {  } }, ["param2"] = 0, ["y"] = 0, ["param1"] = 13, ["z"] = 7, ["name"] = "default:wood" }, { ["x"] = 9, ["meta"] = { ["fields"] = {  }, ["inventory"] = {  } }, ["param2"] = 0, ["y"] = 1, ["param1"] = 0, ["z"] = 1, ["name"] = "default:wood" }, { ["x"] = 9, ["meta"] = { ["fields"] = {  }, ["inventory"] = {  } }, ["param2"] = 2, ["y"] = 1, ["param1"] = 187, ["z"] = 2, ["name"] = "stairs:stair_wood" }, { ["x"] = 9, ["meta"] = { ["fields"] = {  }, ["inventory"] = {  } }, ["param2"] = 0, ["y"] = 1, ["param1"] = 171, ["z"] = 6, ["name"] = "stairs:stair_wood" }, { ["x"] = 9, ["meta"] = { ["fields"] = {  }, ["inventory"] = {  } }, ["param2"] = 0, ["y"] = 1, ["param1"] = 0, ["z"] = 7, ["name"] = "default:wood" }, { ["x"] = 9, ["meta"] = { ["fields"] = {  }, ["inventory"] = {  } }, ["param2"] = 0, ["y"] = 2, ["param1"] = 0, ["z"] = 1, ["name"] = "default:wood" }, { ["x"] = 9, ["meta"] = { ["fields"] = {  }, ["inventory"] = {  } }, ["param2"] = 0, ["y"] = 2, ["param1"] = 0, ["z"] = 7, ["name"] = "default:wood" }, { ["x"] = 9, ["meta"] = { ["fields"] = {  }, ["inventory"] = {  } }, ["param2"] = 0, ["y"] = 3, ["param1"] = 205, ["z"] = 1, ["name"] = "stairs:stair_wood" }, { ["x"] = 9, ["meta"] = { ["fields"] = {  }, ["inventory"] = {  } }, ["param2"] = 5, ["y"] = 3, ["param1"] = 0, ["z"] = 2, ["name"] = "default:torch" }, { ["x"] = 9, ["meta"] = { ["fields"] = {  }, ["inventory"] = {  } }, ["param2"] = 2, ["y"] = 3, ["param1"] = 189, ["z"] = 7, ["name"] = "stairs:stair_wood" }, { ["x"] = 9, ["meta"] = { ["fields"] = {  }, ["inventory"] = {  } }, ["param2"] = 0, ["y"] = 4, ["param1"] = 205, ["z"] = 2, ["name"] = "stairs:slab_wood" }, { ["x"] = 9, ["meta"] = { ["fields"] = {  }, ["inventory"] = {  } }, ["param2"] = 0, ["y"] = 4, ["param1"] = 189, ["z"] = 3, ["name"] = "stairs:slab_wood" }, { ["x"] = 9, ["meta"] = { ["fields"] = {  }, ["inventory"] = {  } }, ["param2"] = 0, ["y"] = 4, ["param1"] = 189, ["z"] = 4, ["name"] = "stairs:slab_wood" }, { ["x"] = 9, ["meta"] = { ["fields"] = {  }, ["inventory"] = {  } }, ["param2"] = 0, ["y"] = 4, ["param1"] = 173, ["z"] = 5, ["name"] = "stairs:slab_wood" }, { ["x"] = 9, ["meta"] = { ["fields"] = {  }, ["inventory"] = {  } }, ["param2"] = 0, ["y"] = 4, ["param1"] = 189, ["z"] = 6, ["name"] = "stairs:slab_wood" }, { ["x"] = 10, ["meta"] = { ["fields"] = {  }, ["inventory"] = {  } }, ["param2"] = 0, ["y"] = 0, ["param1"] = 95, ["z"] = 1, ["name"] = "default:wood" }, { ["x"] = 10, ["meta"] = { ["fields"] = {  }, ["inventory"] = {  } }, ["param2"] = 0, ["y"] = 0, ["param1"] = 79, ["z"] = 2, ["name"] = "default:wood" }, { ["x"] = 10, ["meta"] = { ["fields"] = {  }, ["inventory"] = {  } }, ["param2"] = 0, ["y"] = 0, ["param1"] = 63, ["z"] = 3, ["name"] = "default:wood" }, { ["x"] = 10, ["meta"] = { ["fields"] = {  }, ["inventory"] = {  } }, ["param2"] = 0, ["y"] = 0, ["param1"] = 47, ["z"] = 4, ["name"] = "default:wood" }, { ["x"] = 10, ["meta"] = { ["fields"] = {  }, ["inventory"] = {  } }, ["param2"] = 0, ["y"] = 0, ["param1"] = 31, ["z"] = 5, ["name"] = "default:wood" }, { ["x"] = 10, ["meta"] = { ["fields"] = {  }, ["inventory"] = {  } }, ["param2"] = 0, ["y"] = 0, ["param1"] = 13, ["z"] = 6, ["name"] = "default:wood" }, { ["x"] = 10, ["meta"] = { ["fields"] = {  }, ["inventory"] = {  } }, ["param2"] = 0, ["y"] = 0, ["param1"] = 13, ["z"] = 7, ["name"] = "default:wood" }, { ["x"] = 10, ["meta"] = { ["fields"] = {  }, ["inventory"] = {  } }, ["param2"] = 0, ["y"] = 1, ["param1"] = 0, ["z"] = 1, ["name"] = "default:wood" }, { ["x"] = 10, ["meta"] = { ["fields"] = {  }, ["inventory"] = {  } }, ["param2"] = 0, ["y"] = 1, ["param1"] = 0, ["z"] = 2, ["name"] = "default:wood" }, { ["x"] = 10, ["meta"] = { ["fields"] = {  }, ["inventory"] = {  } }, ["param2"] = 0, ["y"] = 1, ["param1"] = 173, ["z"] = 3, ["name"] = "default:glass" }, { ["x"] = 10, ["meta"] = { ["fields"] = {  }, ["inventory"] = {  } }, ["param2"] = 0, ["y"] = 1, ["param1"] = 157, ["z"] = 4, ["name"] = "default:glass" }, { ["x"] = 10, ["meta"] = { ["fields"] = {  }, ["inventory"] = {  } }, ["param2"] = 0, ["y"] = 1, ["param1"] = 173, ["z"] = 5, ["name"] = "default:glass" }, { ["x"] = 10, ["meta"] = { ["fields"] = {  }, ["inventory"] = {  } }, ["param2"] = 0, ["y"] = 1, ["param1"] = 0, ["z"] = 6, ["name"] = "default:wood" }, { ["x"] = 10, ["meta"] = { ["fields"] = {  }, ["inventory"] = {  } }, ["param2"] = 0, ["y"] = 1, ["param1"] = 0, ["z"] = 7, ["name"] = "default:wood" }, { ["x"] = 10, ["meta"] = { ["fields"] = {  }, ["inventory"] = {  } }, ["param2"] = 0, ["y"] = 2, ["param1"] = 0, ["z"] = 1, ["name"] = "default:wood" }, { ["x"] = 10, ["meta"] = { ["fields"] = {  }, ["inventory"] = {  } }, ["param2"] = 0, ["y"] = 2, ["param1"] = 0, ["z"] = 2, ["name"] = "default:wood" }, { ["x"] = 10, ["meta"] = { ["fields"] = {  }, ["inventory"] = {  } }, ["param2"] = 0, ["y"] = 2, ["param1"] = 189, ["z"] = 3, ["name"] = "default:glass" }, { ["x"] = 10, ["meta"] = { ["fields"] = {  }, ["inventory"] = {  } }, ["param2"] = 0, ["y"] = 2, ["param1"] = 173, ["z"] = 4, ["name"] = "default:glass" }, { ["x"] = 10, ["meta"] = { ["fields"] = {  }, ["inventory"] = {  } }, ["param2"] = 0, ["y"] = 2, ["param1"] = 189, ["z"] = 5, ["name"] = "default:glass" }, { ["x"] = 10, ["meta"] = { ["fields"] = {  }, ["inventory"] = {  } }, ["param2"] = 0, ["y"] = 2, ["param1"] = 0, ["z"] = 6, ["name"] = "default:wood" }, { ["x"] = 10, ["meta"] = { ["fields"] = {  }, ["inventory"] = {  } }, ["param2"] = 0, ["y"] = 2, ["param1"] = 0, ["z"] = 7, ["name"] = "default:wood" }, { ["x"] = 10, ["meta"] = { ["fields"] = {  }, ["inventory"] = {  } }, ["param2"] = 0, ["y"] = 3, ["param1"] = 189, ["z"] = 1, ["name"] = "stairs:slab_wood" }, { ["x"] = 10, ["meta"] = { ["fields"] = {  }, ["inventory"] = {  } }, ["param2"] = 3, ["y"] = 3, ["param1"] = 205, ["z"] = 2, ["name"] = "stairs:stair_wood" }, { ["x"] = 10, ["meta"] = { ["fields"] = {  }, ["inventory"] = {  } }, ["param2"] = 3, ["y"] = 3, ["param1"] = 189, ["z"] = 3, ["name"] = "stairs:stair_wood" }, { ["x"] = 10, ["meta"] = { ["fields"] = {  }, ["inventory"] = {  } }, ["param2"] = 3, ["y"] = 3, ["param1"] = 189, ["z"] = 4, ["name"] = "stairs:stair_wood" }, { ["x"] = 10, ["meta"] = { ["fields"] = {  }, ["inventory"] = {  } }, ["param2"] = 3, ["y"] = 3, ["param1"] = 173, ["z"] = 5, ["name"] = "stairs:stair_wood" }, { ["x"] = 10, ["meta"] = { ["fields"] = {  }, ["inventory"] = {  } }, ["param2"] = 3, ["y"] = 3, ["param1"] = 189, ["z"] = 6, ["name"] = "stairs:stair_wood" }, { ["x"] = 10, ["meta"] = { ["fields"] = {  }, ["inventory"] = {  } }, ["param2"] = 0, ["y"] = 3, ["param1"] = 173, ["z"] = 7, ["name"] = "stairs:slab_wood" }, { ["x"] = 11, ["meta"] = { ["fields"] = {  }, ["inventory"] = {  } }, ["param2"] = 3, ["y"] = 2, ["param1"] = 15, ["z"] = 2, ["name"] = "default:torch" }, { ["x"] = 11, ["meta"] = { ["fields"] = {  }, ["inventory"] = {  } }, ["param2"] = 3, ["y"] = 2, ["param1"] = 15, ["z"] = 6, ["name"] = "default:torch" } }